<?xml version="1.0" ?>
<!-- =================================================================================== -->
<!-- |    This document was autogenerated by xacro from nao_robot.xacro                | -->
<!-- |    EDITING THIS FILE BY HAND IS NOT RECOMMENDED                                 | -->
<!-- =================================================================================== -->
<!--******************************************************************
 ****** File automatically generated by generate_urdf.py script ******
 *********************************************************************-->
<robot name="nao" xmlns:xacro="http://www.ros.org/wiki/xacro">
  <joint name="HeadYaw" type="revolute">
    <parent link="torso"/>
    <child link="Neck"/>
    <origin rpy="0 0 0" xyz="0 0 0.1265"/>
    <axis xyz="0 0 1.0"/>
    <limit effort="1.547" lower="-2.08567" upper="2.08567" velocity="8.26797"/>
  </joint>
  <link name="Neck">
    <inertial>
      <mass value="0.07842"/>
      <inertia ixx="1.60324e-05" ixy="1.57e-09" ixz="3.16276e-09" iyy="1.70394e-05" iyz="-5.295e-08" izz="5.53372e-06"/>
      <origin rpy="0 0 0" xyz="-1e-05 0 -0.02742"/>
    </inertial>
    <visual>
      <geometry>
        <mesh filename="package://nao_meshes/meshes/V40/HeadYaw.dae" scale="0.1 0.1 0.1"/>
      </geometry>
      <origin rpy="0 0 0" xyz="0 0 0"/>
    </visual>
    <collision>
      <geometry>
        <mesh filename="package://nao_meshes/meshes/V40/HeadYaw_0.10.stl" scale="0.1 0.1 0.1"/>
      </geometry>
      <origin rpy="0 0 0" xyz="0 0 0"/>
    </collision>
  </link>
  <joint name="HeadPitch" type="revolute">
    <parent link="Neck"/>
    <child link="Head"/>
    <origin rpy="0 0 0" xyz="0 0 0"/>
    <axis xyz="0 1.0 0"/>
    <limit effort="1.532" lower="-0.671952" upper="0.514872" velocity="7.19407"/>
  </joint>
  <link name="Head">
    <inertial>
      <mass value="0.60533"/>
      <inertia ixx="0.000957766" ixy="8.78814e-06" ixz="5.33702e-06" iyy="0.000816836" iyz="-2.99579e-05" izz="0.000984976"/>
      <origin rpy="0 0 0" xyz="-0.00112 0 0.05258"/>
    </inertial>
    <visual>
      <geometry>
        <mesh filename="package://nao_meshes/meshes/V40/HeadPitch.dae" scale="0.1 0.1 0.1"/>
      </geometry>
      <origin rpy="0 0 0" xyz="0 0 0"/>
    </visual>
    <collision>
      <geometry>
        <mesh filename="package://nao_meshes/meshes/V40/HeadPitch_0.10.stl" scale="0.1 0.1 0.1"/>
      </geometry>
      <origin rpy="0 0 0" xyz="0 0 0"/>
    </collision>
  </link>
  <joint name="gaze_joint" type="fixed">
    <parent link="Head"/>
    <child link="gaze"/>
    <origin rpy="0 0 0" xyz="0.05871 0 0.06364"/>
  </joint>
  <link name="gaze">
      <inertial>
      <mass value="1e-9"/>
      <inertia ixx="0.0" ixy="0.0" ixz="0.0" iyy="0.0" iyz="0.0" izz="0.0"/>
      <origin rpy="0 0 0" xyz="0.0 0.0 0.0"/>
    </inertial>
  </link>
  <joint name="LHipYawPitch" type="revolute">
    <parent link="torso"/>
    <child link="LPelvis"/>
    <origin rpy="0 0 0" xyz="0 0.05 -0.085"/>
    <axis xyz="0 0.707106 -0.707106"/>
    <limit effort="3.348" lower="-1.14529" upper="0.740718" velocity="4.16174"/>
  </joint>
  <link name="LPelvis">
    <inertial>
      <mass value="0.06981"/>
      <inertia ixx="2.3407e-05" ixy="1.07922e-06" ixz="-1.76003e-06" iyy="4.76355e-05" iyz="2.76058e-06" izz="4.97021e-05"/>
      <origin rpy="0 0 0" xyz="-0.00781 -0.01114 0.02661"/>
    </inertial>
    <visual>
      <geometry>
        <mesh filename="package://nao_meshes/meshes/V40/LHipYawPitch.dae" scale="0.1 0.1 0.1"/>
      </geometry>
      <origin rpy="0 0 0" xyz="0 0 0"/>
    </visual>
    <collision>
      <geometry>
        <mesh filename="package://nao_meshes/meshes/V40/LHipYawPitch_0.10.stl" scale="0.1 0.1 0.1"/>
      </geometry>
      <origin rpy="0 0 0" xyz="0 0 0"/>
    </collision>
  </link>
  <joint name="LHipRoll" type="revolute">
    <parent link="LPelvis"/>
    <child link="LHip"/>
    <origin rpy="0 0 0" xyz="0 0 0"/>
    <axis xyz="1.0 0 0"/>
    <limit effort="3.348" lower="-0.379435" upper="0.79046" velocity="4.16174"/>
  </joint>
  <link name="LHip">
    <inertial>
      <mass value="0.14053"/>
      <inertia ixx="2.38445e-05" ixy="-6.53605e-07" ixz="7.12893e-06" iyy="6.08246e-05" iyz="-2.14072e-07" izz="5.43691e-05"/>
      <origin rpy="0 0 0" xyz="-0.01549 0.00029 -0.00515"/>
    </inertial>
    <visual>
      <geometry>
        <mesh filename="package://nao_meshes/meshes/V40/LHipRoll.dae" scale="0.1 0.1 0.1"/>
      </geometry>
      <origin rpy="0 0 0" xyz="0 0 0"/>
    </visual>
    <collision>
      <geometry>
        <mesh filename="package://nao_meshes/meshes/V40/LHipRoll_0.10.stl" scale="0.1 0.1 0.1"/>
      </geometry>
      <origin rpy="0 0 0" xyz="0 0 0"/>
    </collision>
  </link>
  <joint name="LHipPitch" type="revolute">
    <parent link="LHip"/>
    <child link="LThigh"/>
    <origin rpy="0 0 0" xyz="0 0 0"/>
    <axis xyz="0 1.0 0"/>
    <limit effort="3.023" lower="-1.53589" upper="0.48398" velocity="6.40239"/>
  </joint>
  <link name="LThigh">
    <inertial>
      <mass value="0.38968"/>
      <inertia ixx="0.000509844" ixy="2.11296e-06" ixz="5.64129e-05" iyy="0.000465358" iyz="-7.91029e-06" izz="0.000301098"/>
      <origin rpy="0 0 0" xyz="0.00138 0.00221 -0.05373"/>
    </inertial>
    <visual>
      <geometry>
        <mesh filename="package://nao_meshes/meshes/V40/LHipPitch.dae" scale="0.1 0.1 0.1"/>
      </geometry>
      <origin rpy="0 0 0" xyz="0 0 0"/>
    </visual>
    <collision>
      <geometry>
        <mesh filename="package://nao_meshes/meshes/V40/LHipPitch_0.10.stl" scale="0.1 0.1 0.1"/>
      </geometry>
      <origin rpy="0 0 0" xyz="0 0 0"/>
    </collision>
  </link>
  <joint name="LKneePitch" type="revolute">
    <parent link="LThigh"/>
    <child link="LTibia"/>
    <origin rpy="0 0 0" xyz="0 0 -0.1"/>
    <axis xyz="0 1.0 0"/>
    <limit effort="3.023" lower="-0.0923279" upper="2.11255" velocity="6.40239"/>
  </joint>
  <link name="LTibia">
    <inertial>
      <mass value="0.30142"/>
      <inertia ixx="0.000446171" ixy="3.70584e-06" ixz="-3.09008e-05" iyy="0.000388084" iyz="6.01953e-06" izz="0.000185516"/>
      <origin rpy="0 0 0" xyz="0.00453 0.00225 -0.04936"/>
    </inertial>
    <visual>
      <geometry>
        <mesh filename="package://nao_meshes/meshes/V40/LKneePitch.dae" scale="0.1 0.1 0.1"/>
      </geometry>
      <origin rpy="0 0 0" xyz="0 0 0"/>
    </visual>
    <collision>
      <geometry>
        <mesh filename="package://nao_meshes/meshes/V40/LKneePitch_0.10.stl" scale="0.1 0.1 0.1"/>
      </geometry>
      <origin rpy="0 0 0" xyz="0 0 0"/>
    </collision>
  </link>
  <joint name="LAnklePitch" type="revolute">
    <parent link="LTibia"/>
    <child link="LAnklePitch"/>
    <origin rpy="0 0 0" xyz="0 0 -0.1029"/>
    <axis xyz="0 1.0 0"/>
    <limit effort="3.023" lower="-1.18944" upper="0.922581" velocity="6.40239"/>
  </joint>
  <link name="LAnklePitch">
    <inertial>
      <mass value="0.13416"/>
      <inertia ixx="3.22034e-05" ixy="-8.83212e-09" ixz="4.27549e-06" iyy="6.7943e-05" iyz="2.84849e-07" izz="5.48269e-05"/>
      <origin rpy="0 0 0" xyz="0.00045 0.00029 0.00685"/>
    </inertial>
    <visual>
      <geometry>
        <mesh filename="package://nao_meshes/meshes/V40/LAnklePitch.dae" scale="0.1 0.1 0.1"/>
      </geometry>
      <origin rpy="0 0 0" xyz="0 0 0"/>
    </visual>
    <collision>
      <geometry>
        <mesh filename="package://nao_meshes/meshes/V40/LAnklePitch_0.10.stl" scale="0.1 0.1 0.1"/>
      </geometry>
      <origin rpy="0 0 0" xyz="0 0 0"/>
    </collision>
  </link>
  <joint name="LAnkleRoll" type="revolute">
    <parent link="LAnklePitch"/>
    <child link="l_ankle"/>
    <origin rpy="0 0 0" xyz="0 0 0"/>
    <axis xyz="1.0 0 0"/>
    <limit effort="3.348" lower="-0.397761" upper="0.768992" velocity="4.16174"/>
  </joint>
  <link name="l_ankle">
    <inertial>
      <mass value="0.17184"/>
      <inertia ixx="8.72911e-05" ixy="8.71925e-06" ixz="-2.10563e-06" iyy="0.000353024" iyz="3.73459e-07" izz="0.000412846"/>
      <origin rpy="0 0 0" xyz="0.02542 0.0033 -0.03239"/>
    </inertial>
    <visual>
      <geometry>
        <mesh filename="package://nao_meshes/meshes/V40/LAnkleRoll.dae" scale="0.1 0.1 0.1"/>
      </geometry>
      <origin rpy="0 0 0" xyz="0 0 0"/>
    </visual>
    <collision>
      <geometry>
        <mesh filename="package://nao_meshes/meshes/V40/LAnkleRoll_0.10.stl" scale="0.1 0.1 0.1"/>
      </geometry>
      <origin rpy="0 0 0" xyz="0 0 0"/>
    </collision>
  </link>
  <joint name="LLeg_effector_fixedjoint" type="fixed">
    <parent link="l_ankle"/>
    <child link="l_sole"/>
    <origin rpy="0 0 0" xyz="0 0 -0.04511"/>
    <axis xyz="0 0 0"/>
  </joint>
  <link name="l_sole">
        <inertial>
      <mass value="1e-9"/>
      <inertia ixx="0.0" ixy="0.0" ixz="0.0" iyy="0.0" iyz="0.0" izz="0.0"/>
      <origin rpy="0 0 0" xyz="0.0 0.0 0.0"/>
    </inertial>
  </link>
  <joint name="RHipYawPitch" type="revolute">
    <parent link="torso"/>
    <child link="RPelvis"/>
    <origin rpy="0 0 0" xyz="0 -0.05 -0.085"/>
    <axis xyz="0 0.707106 0.707106"/>
    <limit effort="3.348" lower="-1.14529" upper="0.740718" velocity="4.16174"/>
  </joint>
  <link name="RPelvis">
    <inertial>
      <mass value="0.06981"/>
      <inertia ixx="3.18766e-05" ixy="-1.07152e-06" ixz="-1.77295e-06" iyy="5.18361e-05" iyz="-7.00664e-06" izz="5.39657e-05"/>
      <origin rpy="0 0 0" xyz="-0.00781 0.01114 0.02661"/>
    </inertial>
    <visual>
      <geometry>
        <mesh filename="package://nao_meshes/meshes/V40/RHipYawPitch.dae" scale="0.1 0.1 0.1"/>
      </geometry>
      <origin rpy="0 0 0" xyz="0 0 0"/>
    </visual>
    <collision>
      <geometry>
        <mesh filename="package://nao_meshes/meshes/V40/RHipYawPitch_0.10.stl" scale="0.1 0.1 0.1"/>
      </geometry>
      <origin rpy="0 0 0" xyz="0 0 0"/>
    </collision>
  </link>
  <joint name="RHipRoll" type="revolute">
    <parent link="RPelvis"/>
    <child link="RHip"/>
    <origin rpy="0 0 0" xyz="0 0 0"/>
    <axis xyz="1.0 0 0"/>
    <limit effort="3.348" lower="-0.79046" upper="0.379435" velocity="4.16174"/>
  </joint>
  <link name="RHip">
    <inertial>
      <mass value="0.14053"/>
      <inertia ixx="2.38475e-05" ixy="6.12085e-07" ixz="7.10235e-06" iyy="6.0824e-05" iyz="2.12392e-07" izz="5.43727e-05"/>
      <origin rpy="0 0 0" xyz="-0.01549 -0.00029 -0.00515"/>
    </inertial>
    <visual>
      <geometry>
        <mesh filename="package://nao_meshes/meshes/V40/RHipRoll.dae" scale="0.1 0.1 0.1"/>
      </geometry>
      <origin rpy="0 0 0" xyz="0 0 0"/>
    </visual>
    <collision>
      <geometry>
        <mesh filename="package://nao_meshes/meshes/V40/RHipRoll_0.10.stl" scale="0.1 0.1 0.1"/>
      </geometry>
      <origin rpy="0 0 0" xyz="0 0 0"/>
    </collision>
  </link>
  <joint name="RHipPitch" type="revolute">
    <parent link="RHip"/>
    <child link="RThigh"/>
    <origin rpy="0 0 0" xyz="0 0 0"/>
    <axis xyz="0 1.0 0"/>
    <limit effort="3.0226" lower="-1.53589" upper="0.48398" velocity="6.40239"/>
  </joint>
  <link name="RThigh">
    <inertial>
      <mass value="0.38968"/>
      <inertia ixx="0.000510607" ixy="-2.02799e-06" ixz="5.69893e-05" iyy="0.0004665" iyz="7.09563e-06" izz="0.000301333"/>
      <origin rpy="0 0 0" xyz="0.00138 -0.00221 -0.05373"/>
    </inertial>
    <visual>
      <geometry>
        <mesh filename="package://nao_meshes/meshes/V40/RHipPitch.dae" scale="0.1 0.1 0.1"/>
      </geometry>
      <origin rpy="0 0 0" xyz="0 0 0"/>
    </visual>
    <collision>
      <geometry>
        <mesh filename="package://nao_meshes/meshes/V40/RHipPitch_0.10.stl" scale="0.1 0.1 0.1"/>
      </geometry>
      <origin rpy="0 0 0" xyz="0 0 0"/>
    </collision>
  </link>
  <joint name="RKneePitch" type="revolute">
    <parent link="RThigh"/>
    <child link="RTibia"/>
    <origin rpy="0 0 0" xyz="0 0 -0.1"/>
    <axis xyz="0 1.0 0"/>
    <limit effort="3.0226" lower="-0.0923279" upper="2.11255" velocity="6.40239"/>
  </joint>
  <link name="RTibia">
    <inertial>
      <mass value="0.30142"/>
      <inertia ixx="0.000446921" ixy="-3.96872e-06" ixz="-3.94009e-05" iyy="0.000387711" iyz="-5.00034e-06" izz="0.000183741"/>
      <origin rpy="0 0 0" xyz="0.00453 -0.00225 -0.04936"/>
    </inertial>
    <visual>
      <geometry>
        <mesh filename="package://nao_meshes/meshes/V40/RKneePitch.dae" scale="0.1 0.1 0.1"/>
      </geometry>
      <origin rpy="0 0 0" xyz="0 0 0"/>
    </visual>
    <collision>
      <geometry>
        <mesh filename="package://nao_meshes/meshes/V40/RKneePitch_0.10.stl" scale="0.1 0.1 0.1"/>
      </geometry>
      <origin rpy="0 0 0" xyz="0 0 0"/>
    </collision>
  </link>
  <joint name="RAnklePitch" type="revolute">
    <parent link="RTibia"/>
    <child link="RAnklePitch"/>
    <origin rpy="0 0 0" xyz="0 0 -0.1029"/>
    <axis xyz="0 1.0 0"/>
    <limit effort="3.0226" lower="-1.1863" upper="0.932006" velocity="6.40239"/>
  </joint>
  <link name="RAnklePitch">
    <inertial>
      <mass value="0.13416"/>
      <inertia ixx="3.22017e-05" ixy="4.68321e-08" ixz="4.28821e-06" iyy="6.79885e-05" iyz="-2.71089e-07" izz="5.48747e-05"/>
      <origin rpy="0 0 0" xyz="0.00045 -0.00029 0.00685"/>
    </inertial>
    <visual>
      <geometry>
        <mesh filename="package://nao_meshes/meshes/V40/RAnklePitch.dae" scale="0.1 0.1 0.1"/>
      </geometry>
      <origin rpy="0 0 0" xyz="0 0 0"/>
    </visual>
    <collision>
      <geometry>
        <mesh filename="package://nao_meshes/meshes/V40/RAnklePitch_0.10.stl" scale="0.1 0.1 0.1"/>
      </geometry>
      <origin rpy="0 0 0" xyz="0 0 0"/>
    </collision>
  </link>
  <joint name="RAnkleRoll" type="revolute">
    <parent link="RAnklePitch"/>
    <child link="r_ankle"/>
    <origin rpy="0 0 0" xyz="0 0 0"/>
    <axis xyz="1.0 0 0"/>
    <limit effort="3.348" lower="-0.768992" upper="0.397761" velocity="4.16174"/>
  </joint>
  <link name="r_ankle">
    <inertial>
      <mass value="0.17184"/>
      <inertia ixx="8.71513e-05" ixy="-8.53992e-06" ixz="-2.35184e-06" iyy="0.000352156" iyz="-4.81708e-07" izz="0.000412125"/>
      <origin rpy="0 0 0" xyz="0.02542 -0.0033 -0.03239"/>
    </inertial>
    <visual>
      <geometry>
        <mesh filename="package://nao_meshes/meshes/V40/RAnkleRoll.dae" scale="0.1 0.1 0.1"/>
      </geometry>
      <origin rpy="0 0 0" xyz="0 0 0"/>
    </visual>
    <collision>
      <geometry>
        <mesh filename="package://nao_meshes/meshes/V40/RAnkleRoll_0.10.stl" scale="0.1 0.1 0.1"/>
      </geometry>
      <origin rpy="0 0 0" xyz="0 0 0"/>
    </collision>
  </link>
  <joint name="RLeg_effector_fixedjoint" type="fixed">
    <parent link="r_ankle"/>
    <child link="r_sole"/>
    <origin rpy="0 0 0" xyz="0 0 -0.04511"/>
    <axis xyz="0 0 0"/>
  </joint>
  <link name="r_sole">
        <inertial>
      <mass value="1e-9"/>
      <inertia ixx="0.0" ixy="0.0" ixz="0.0" iyy="0.0" iyz="0.0" izz="0.0"/>
      <origin rpy="0 0 0" xyz="0.0 0.0 0.0"/>
    </inertial>
  </link>
  <link name="base_link">
        <inertial>
      <mass value="0.001"/>
      <inertia ixx="0.0" ixy="0.0" ixz="0.0" iyy="0.0" iyz="0.0" izz="0.0"/>
      <origin rpy="0 0 0" xyz="0.0 0.0 0.0"/>
    </inertial>
  </link>
  <joint name="base_link_fixedjoint" type="fixed">
    <parent link="base_link"/>
    <child link="torso"/>
    <origin rpy="0 0 0" xyz="0 0 0"/>
    <axis xyz="0 0 0"/>
  </joint>
  <link name="torso">
    <inertial>
      <mass value="1.04956"/>
      <inertia ixx="0.00308361" ixy="1.43116e-05" ixz="-3.30211e-05" iyy="0.0028835" iyz="-2.70793e-05" izz="0.0015924"/>
      <origin rpy="0 0 0" xyz="-0.00413 0 0.04342"/>
    </inertial>
    <visual>
      <geometry>
        <mesh filename="package://nao_meshes/meshes/V40/Torso.dae" scale="0.1 0.1 0.1"/>
      </geometry>
      <origin rpy="0 0 0" xyz="0 0 0"/>
    </visual>
    <collision>
      <geometry>
        <mesh filename="package://nao_meshes/meshes/V40/Torso_0.10.stl" scale="0.1 0.1 0.1"/>
      </geometry>
      <origin rpy="0 0 0" xyz="0 0 0"/>
    </collision>
  </link>
  <joint name="LShoulderPitch" type="revolute">
    <parent link="torso"/>
    <child link="LShoulder"/>
    <origin rpy="0 0 0" xyz="0 0.098 0.1"/>
    <axis xyz="0 1.0 0"/>
    <limit effort="1.329" lower="-2.08567" upper="2.08567" velocity="8.26797"/>
  </joint>
  <link name="LShoulder">
    <inertial>
      <mass value="0.09304"/>
      <inertia ixx="1.83025e-05" ixy="2.06011e-06" ixz="1.88776e-09" iyy="1.39005e-05" iyz="-3.66592e-07" izz="2.01862e-05"/>
      <origin rpy="0 0 0" xyz="-0.00165 -0.02663 0.00014"/>
    </inertial>
    <visual>
      <geometry>
        <mesh filename="package://nao_meshes/meshes/V40/LShoulderPitch.dae" scale="0.1 0.1 0.1"/>
      </geometry>
      <origin rpy="0 0 0" xyz="0 0 0"/>
    </visual>
    <collision>
      <geometry>
        <mesh filename="package://nao_meshes/meshes/V40/LShoulderPitch_0.10.stl" scale="0.1 0.1 0.1"/>
      </geometry>
      <origin rpy="0 0 0" xyz="0 0 0"/>
    </collision>
  </link>
  <joint name="LShoulderRoll" type="revolute">
    <parent link="LShoulder"/>
    <child link="LBicep"/>
    <origin rpy="0 0 0" xyz="0 0 0"/>
    <axis xyz="0 0 1.0"/>
    <limit effort="1.7835" lower="-0.314159" upper="1.32645" velocity="7.19407"/>
  </joint>
  <link name="LBicep">
    <inertial>
      <mass value="0.15777"/>
      <inertia ixx="8.7181e-05" ixy="-2.53381e-05" ixz="-1.4213e-05" iyy="0.000274712" iyz="4.71439e-07" izz="0.000241812"/>
      <origin rpy="0 0 0" xyz="0.02455 0.00563 0.0033"/>
    </inertial>
    <visual>
      <geometry>
        <mesh filename="package://nao_meshes/meshes/V40/LShoulderRoll.dae" scale="0.1 0.1 0.1"/>
      </geometry>
      <origin rpy="0 0 0" xyz="0 0 0"/>
    </visual>
    <collision>
      <geometry>
        <mesh filename="package://nao_meshes/meshes/V40/LShoulderRoll_0.10.stl" scale="0.1 0.1 0.1"/>
      </geometry>
      <origin rpy="0 0 0" xyz="0 0 0"/>
    </collision>
  </link>
  <joint name="LElbowYaw" type="revolute">
    <parent link="LBicep"/>
    <child link="LElbow"/>
    <origin rpy="0 0 0" xyz="0.105 0.015 0"/>
    <axis xyz="1.0 0 0"/>
    <limit effort="1.547" lower="-2.08567" upper="2.08567" velocity="8.26797"/>
  </joint>
  <link name="LElbow">
    <inertial>
      <mass value="0.06483"/>
      <inertia ixx="5.59588e-06" ixy="4.21e-09" ixz="2.92241e-07" iyy="2.66179e-05" iyz="-1.84e-09" izz="2.76294e-05"/>
      <origin rpy="0 0 0" xyz="-0.02744 0 -0.00014"/>
    </inertial>
  </link>
  <joint name="RShoulderPitch" type="revolute">
    <parent link="torso"/>
    <child link="RShoulder"/>
    <origin rpy="0 0 0" xyz="0 -0.098 0.1"/>
    <axis xyz="0 1.0 0"/>
    <limit effort="1.329" lower="-2.08567" upper="2.08567" velocity="8.26797"/>
  </joint>
  <link name="RShoulder">
    <inertial>
      <mass value="0.09304"/>
      <inertia ixx="1.83025e-05" ixy="-2.06011e-06" ixz="1.88776e-09" iyy="1.39005e-05" iyz="3.66592e-07" izz="2.01862e-05"/>
      <origin rpy="0 0 0" xyz="-0.00165 0.02663 0.00014"/>
    </inertial>
    <visual>
      <geometry>
        <mesh filename="package://nao_meshes/meshes/V40/RShoulderPitch.dae" scale="0.1 0.1 0.1"/>
      </geometry>
      <origin rpy="0 0 0" xyz="0 0 0"/>
    </visual>
    <collision>
      <geometry>
        <mesh filename="package://nao_meshes/meshes/V40/RShoulderPitch_0.10.stl" scale="0.1 0.1 0.1"/>
      </geometry>
      <origin rpy="0 0 0" xyz="0 0 0"/>
    </collision>
  </link>
  <joint name="RShoulderRoll" type="revolute">
    <parent link="RShoulder"/>
    <child link="RBicep"/>
    <origin rpy="0 0 0" xyz="0 0 0"/>
    <axis xyz="0 0 1.0"/>
    <limit effort="1.783" lower="-1.32645" upper="0.314159" velocity="7.19407"/>
  </joint>
  <link name="RBicep">
    <inertial>
      <mass value="0.15777"/>
      <inertia ixx="0.000103401" ixy="5.48849e-05" ixz="-1.32643e-05" iyy="0.00027077" iyz="9.16707e-06" izz="0.000254529"/>
      <origin rpy="0 0 0" xyz="0.02455 -0.00563 0.0033"/>
    </inertial>
    <visual>
      <geometry>
        <mesh filename="package://nao_meshes/meshes/V40/RShoulderRoll.dae" scale="0.1 0.1 0.1"/>
      </geometry>
      <origin rpy="0 0 0" xyz="0 0 0"/>
    </visual>
    <collision>
      <geometry>
        <mesh filename="package://nao_meshes/meshes/V40/RShoulderRoll_0.10.stl" scale="0.1 0.1 0.1"/>
      </geometry>
      <origin rpy="0 0 0" xyz="0 0 0"/>
    </collision>
  </link>
  <joint name="RElbowYaw" type="revolute">
    <parent link="RBicep"/>
    <child link="RElbow"/>
    <origin rpy="0 0 0" xyz="0.105 -0.015 0"/>
    <axis xyz="1.0 0 0"/>
    <limit effort="1.547" lower="-2.08567" upper="2.08567" velocity="8.26797"/>
  </joint>
  <link name="RElbow">
    <inertial>
      <mass value="0.06483"/>
      <inertia ixx="5.59588e-06" ixy="4.21e-09" ixz="2.92241e-07" iyy="2.66179e-05" iyz="-1.84e-09" izz="2.76294e-05"/>
      <origin rpy="0 0 0" xyz="-0.02744 0 -0.00014"/>
    </inertial>
  </link>
  <link name="LFootBumperRight_frame">
        <inertial>
      <mass value="1e-9"/>
      <inertia ixx="0.0" ixy="0.0" ixz="0.0" iyy="0.0" iyz="0.0" izz="0.0"/>
      <origin rpy="0 0 0" xyz="0.0 0.0 0.0"/>
    </inertial>
  </link>
  <joint name="LFoot/Bumper/Right_sensor_fixedjoint" type="fixed">
    <parent link="l_ankle"/>
    <child link="LFootBumperRight_frame"/>
    <origin rpy="0 0 0" xyz="0.0876 -0.014 -0.0353"/>
    <axis xyz="0 0 0"/>
  </joint>
  <link name="RFsrRL_frame">
    <collision>
      <geometry>
        <box size="0.01 0.01 0.005"/>
      </geometry>
      <origin rpy="0 0 0" xyz="0 0 0"/>
    </collision>
    <inertial>
      <mass value="2e-06"/>
      <inertia ixx="1.1e-09" ixy="0" ixz="0" iyy="1.1e-09" iyz="0" izz="1.1e-09"/>
      <origin xyz="0 0 0" rpy="0 0 0" />

    </inertial>
  </link>
  <joint name="RFoot/FSR/RearLeft_sensor_fixedjoint" type="fixed">
    <parent link="r_ankle"/>
    <child link="RFsrRL_frame"/>
    <origin rpy="0 0 0" xyz="-0.03025 0.0191 -0.04511"/>
    <axis xyz="0 0 0"/>
  </joint>
  <link name="CameraBottom_optical_frame">
        <inertial>
      <mass value="1e-9"/>
      <inertia ixx="0.0" ixy="0.0" ixz="0.0" iyy="0.0" iyz="0.0" izz="0.0"/>
      <origin rpy="0 0 0" xyz="0.0 0.0 0.0"/>
    </inertial>
  </link>
  <joint name="CameraBottom_optical_frame_fixedjoint" type="fixed">
    <parent link="CameraBottom_frame"/>
    <child link="CameraBottom_optical_frame"/>
    <origin rpy="-1.57079632679 0 -1.57079632679" xyz="0 0 0"/>
  </joint>
  <link name="RFsrRR_frame">
    <collision>
      <geometry>
        <box size="0.01 0.01 0.005"/>
      </geometry>
      <origin rpy="0 0 0" xyz="0 0 0"/>
    </collision>
    <inertial>
      <mass value="2e-06"/>
      <inertia ixx="1.1e-09" ixy="0" ixz="0" iyy="1.1e-09" iyz="0" izz="1.1e-09"/>
      <origin xyz="0 0 0" rpy="0 0 0" />

    </inertial>
  </link>
  <joint name="RFoot/FSR/RearRight_sensor_fixedjoint" type="fixed">
    <parent link="r_ankle"/>
    <child link="RFsrRR_frame"/>
    <origin rpy="0 0 0" xyz="-0.02965 -0.0299 -0.04511"/>
    <axis xyz="0 0 0"/>
  </joint>
  <link name="LFsrFR_frame">
    <collision>
      <geometry>
        <box size="0.01 0.01 0.005"/>
      </geometry>
      <origin rpy="0 0 0" xyz="0 0 0"/>
    </collision>
    <inertial>
      <mass value="2e-06"/>
      <inertia ixx="1.1e-09" ixy="0" ixz="0" iyy="1.1e-09" iyz="0" izz="1.1e-09"/>
      <origin xyz="0 0 0" rpy="0 0 0" />

    </inertial>
  </link>
  <joint name="LFoot/FSR/FrontRight_sensor_fixedjoint" type="fixed">
    <parent link="l_ankle"/>
    <child link="LFsrFR_frame"/>
    <origin rpy="0 0 0" xyz="0.07025 -0.0231 -0.04511"/>
    <axis xyz="0 0 0"/>
  </joint>
  <link name="RFootBumperRight_frame">
        <inertial>
      <mass value="1e-9"/>
      <inertia ixx="0.0" ixy="0.0" ixz="0.0" iyy="0.0" iyz="0.0" izz="0.0"/>
      <origin rpy="0 0 0" xyz="0.0 0.0 0.0"/>
    </inertial>
  </link>
  <joint name="RFoot/Bumper/Right_sensor_fixedjoint" type="fixed">
    <parent link="r_ankle"/>
    <child link="RFootBumperRight_frame"/>
    <origin rpy="0 0 0" xyz="0.0876 -0.019 -0.0353"/>
    <axis xyz="0 0 0"/>
  </joint>
  <link name="RFsrFR_frame">
    <collision>
      <geometry>
        <box size="0.01 0.01 0.005"/>
      </geometry>
      <origin rpy="0 0 0" xyz="0 0 0"/>
    </collision>
    <inertial>
      <mass value="2e-06"/>
      <inertia ixx="1.1e-09" ixy="0" ixz="0" iyy="1.1e-09" iyz="0" izz="1.1e-09"/>
      <origin xyz="0 0 0" rpy="0 0 0" />

    </inertial>
  </link>
  <joint name="RFoot/FSR/FrontRight_sensor_fixedjoint" type="fixed">
    <parent link="r_ankle"/>
    <child link="RFsrFR_frame"/>
    <origin rpy="0 0 0" xyz="0.07025 -0.0299 -0.04511"/>
    <axis xyz="0 0 0"/>
  </joint>
  <link name="LFsrRR_frame">
    <collision>
      <geometry>
        <box size="0.01 0.01 0.005"/>
      </geometry>
      <origin rpy="0 0 0" xyz="0 0 0"/>
    </collision>
    <inertial>
      <mass value="2e-06"/>
      <inertia ixx="1.1e-09" ixy="0" ixz="0" iyy="1.1e-09" iyz="0" izz="1.1e-09"/>
      <origin xyz="0 0 0" rpy="0 0 0" />

    </inertial>
  </link>
  <joint name="LFoot/FSR/RearRight_sensor_fixedjoint" type="fixed">
    <parent link="l_ankle"/>
    <child link="LFsrRR_frame"/>
    <origin rpy="0 0 0" xyz="-0.02965 -0.0191 -0.04511"/>
    <axis xyz="0 0 0"/>
  </joint>
  <link name="imu_frame">
        <inertial>
      <mass value="1e-9"/>
      <inertia ixx="0.0" ixy="0.0" ixz="0.0" iyy="0.0" iyz="0.0" izz="0.0"/>
      <origin rpy="0 0 0" xyz="0.0 0.0 0.0"/>
    </inertial>
  </link>
  <joint name="Accelerometer_sensor_fixedjoint" type="fixed">
    <parent link="torso"/>
    <child link="imu_frame"/>
    <origin rpy="0 0 0" xyz="-0.008 0.00606 0.027"/>
    <axis xyz="0 0 0"/>
  </joint>
  <link name="HeadTouchFront_frame">
        <inertial>
      <mass value="1e-9"/>
      <inertia ixx="0.0" ixy="0.0" ixz="0.0" iyy="0.0" iyz="0.0" izz="0.0"/>
      <origin rpy="0 0 0" xyz="0.0 0.0 0.0"/>
    </inertial>
  </link>
  <joint name="Head/Touch/Front_sensor_fixedjoint" type="fixed">
    <parent link="Head"/>
    <child link="HeadTouchFront_frame"/>
    <origin rpy="0 -1.1861 0" xyz="0.0312 0 0.1014"/>
    <axis xyz="0 0 0"/>
  </joint>
  <link name="RFootBumperLeft_frame">
        <inertial>
      <mass value="1e-9"/>
      <inertia ixx="0.0" ixy="0.0" ixz="0.0" iyy="0.0" iyz="0.0" izz="0.0"/>
      <origin rpy="0 0 0" xyz="0.0 0.0 0.0"/>
    </inertial>
  </link>
  <joint name="RFoot/Bumper/Left_sensor_fixedjoint" type="fixed">
    <parent link="r_ankle"/>
    <child link="RFootBumperLeft_frame"/>
    <origin rpy="0 0 0" xyz="0.0876 0.014 -0.0353"/>
    <axis xyz="0 0 0"/>
  </joint>
  <link name="RSonar_frame">
        <inertial>
      <mass value="1e-9"/>
      <inertia ixx="0.0" ixy="0.0" ixz="0.0" iyy="0.0" iyz="0.0" izz="0.0"/>
      <origin rpy="0 0 0" xyz="0.0 0.0 0.0"/>
    </inertial>
  </link>
  <joint name="Sonar/Right_sensor_fixedjoint" type="fixed">
    <parent link="torso"/>
    <child link="RSonar_frame"/>
    <origin rpy="0.00478508 0.0436497 -0.392441" xyz="0.00558253 -0.0192068 0.0623853"/>
    <axis xyz="0 0 0"/>
  </joint>
  <link name="RFsrFL_frame">
    <collision>
      <geometry>
        <box size="0.01 0.01 0.005"/>
      </geometry>
      <origin rpy="0 0 0" xyz="0 0 0"/>
    </collision>
    <inertial>
      <mass value="2e-06"/>
      <inertia ixx="1.1e-09" ixy="0" ixz="0" iyy="1.1e-09" iyz="0" izz="1.1e-09"/>
      <origin xyz="0 0 0" rpy="0 0 0" />

    </inertial>
  </link>
  <joint name="RFoot/FSR/FrontLeft_sensor_fixedjoint" type="fixed">
    <parent link="r_ankle"/>
    <child link="RFsrFL_frame"/>
    <origin rpy="0 0 0" xyz="0.07025 0.0231 -0.04511"/>
    <axis xyz="0 0 0"/>
  </joint>
  <link name="LSonar_frame">
        <inertial>
      <mass value="1e-9"/>
      <inertia ixx="0.0" ixy="0.0" ixz="0.0" iyy="0.0" iyz="0.0" izz="0.0"/>
      <origin rpy="0 0 0" xyz="0.0 0.0 0.0"/>
    </inertial>
  </link>
  <joint name="Sonar/Left_sensor_fixedjoint" type="fixed">
    <parent link="torso"/>
    <child link="LSonar_frame"/>
    <origin rpy="-0.00478508 0.0436497 0.392441" xyz="0.00558253 0.0192068 0.0623853"/>
    <axis xyz="0 0 0"/>
  </joint>
  <link name="LFsrFL_frame">
    <collision>
      <geometry>
        <box size="0.01 0.01 0.005"/>
      </geometry>
      <origin rpy="0 0 0" xyz="0 0 0"/>
    </collision>
    <inertial>
      <mass value="2e-06"/>
      <inertia ixx="1.1e-09" ixy="0" ixz="0" iyy="1.1e-09" iyz="0" izz="1.1e-09"/>
      <origin xyz="0 0 0" rpy="0 0 0" />

    </inertial>
  </link>
  <joint name="LFoot/FSR/FrontLeft_sensor_fixedjoint" type="fixed">
    <parent link="l_ankle"/>
    <child link="LFsrFL_frame"/>
    <origin rpy="0 0 0" xyz="0.07025 0.0299 -0.04511"/>
    <axis xyz="0 0 0"/>
  </joint>
  <link name="LFsrRL_frame">
    <collision>
      <geometry>
        <box size="0.01 0.01 0.005"/>
      </geometry>
      <origin rpy="0 0 0" xyz="0 0 0"/>
    </collision>
    <inertial>
      <mass value="2e-06"/>
      <inertia ixx="1.1e-09" ixy="0" ixz="0" iyy="1.1e-09" iyz="0" izz="1.1e-09"/>
      <origin xyz="0 0 0" rpy="0 0 0" />

    </inertial>
  </link>
  <joint name="LFoot/FSR/RearLeft_sensor_fixedjoint" type="fixed">
    <parent link="l_ankle"/>
    <child link="LFsrRL_frame"/>
    <origin rpy="0 0 0" xyz="-0.03025 0.0299 -0.04511"/>
    <axis xyz="0 0 0"/>
  </joint>
  <link name="CameraBottom_frame">
        <inertial>
      <mass value="1e-9"/>
      <inertia ixx="0.0" ixy="0.0" ixz="0.0" iyy="0.0" iyz="0.0" izz="0.0"/>
      <origin rpy="0 0 0" xyz="0.0 0.0 0.0"/>
    </inertial>
  </link>
  <joint name="CameraBottom_sensor_fixedjoint" type="fixed">
    <parent link="Head"/>
    <child link="CameraBottom_frame"/>
    <origin rpy="0 0.692896 0" xyz="0.05071 0 0.01774"/>
    <axis xyz="0 0 0"/>
  </joint>
  <link name="CameraTop_frame">
        <inertial>
      <mass value="1e-9"/>
      <inertia ixx="0.0" ixy="0.0" ixz="0.0" iyy="0.0" iyz="0.0" izz="0.0"/>
      <origin rpy="0 0 0" xyz="0.0 0.0 0.0"/>
    </inertial>
  </link>
  <joint name="CameraTop_sensor_fixedjoint" type="fixed">
    <parent link="Head"/>
    <child link="CameraTop_frame"/>
    <origin rpy="0 0.0209435 0" xyz="0.05871 0 0.06364"/>
    <axis xyz="0 0 0"/>
  </joint>
  <link name="CameraTop_optical_frame">
        <inertial>
      <mass value="1e-9"/>
      <inertia ixx="0.0" ixy="0.0" ixz="0.0" iyy="0.0" iyz="0.0" izz="0.0"/>
      <origin rpy="0 0 0" xyz="0.0 0.0 0.0"/>
    </inertial>
  </link>
  <joint name="CameraTop_optical_frame_fixedjoint" type="fixed">
    <parent link="CameraTop_frame"/>
    <child link="CameraTop_optical_frame"/>
    <origin rpy="-1.57079632679 0 -1.57079632679" xyz="0 0 0"/>
  </joint>
  <link name="ImuTorsoGyrometer_frame">
        <inertial>
      <mass value="1e-9"/>
      <inertia ixx="0.0" ixy="0.0" ixz="0.0" iyy="0.0" iyz="0.0" izz="0.0"/>
      <origin rpy="0 0 0" xyz="0.0 0.0 0.0"/>
    </inertial>
  </link>
  <joint name="Gyrometer_sensor_fixedjoint" type="fixed">
    <parent link="torso"/>
    <child link="ImuTorsoGyrometer_frame"/>
    <origin rpy="0 0 0" xyz="-0.008 0.006 0.029"/>
    <axis xyz="0 0 0"/>
  </joint>
  <link name="HeadTouchRear_frame">
        <inertial>
      <mass value="1e-9"/>
      <inertia ixx="0.0" ixy="0.0" ixz="0.0" iyy="0.0" iyz="0.0" izz="0.0"/>
      <origin rpy="0 0 0" xyz="0.0 0.0 0.0"/>
    </inertial>
  </link>
  <joint name="Head/Touch/Rear_sensor_fixedjoint" type="fixed">
    <parent link="Head"/>
    <child link="HeadTouchRear_frame"/>
    <origin rpy="3.14159 -1.33319 -3.14159" xyz="-0.0257 0 0.1045"/>
    <axis xyz="0 0 0"/>
  </joint>
  <link name="HeadTouchMiddle_frame">
        <inertial>
      <mass value="1e-9"/>
      <inertia ixx="0.0" ixy="0.0" ixz="0.0" iyy="0.0" iyz="0.0" izz="0.0"/>
      <origin rpy="0 0 0" xyz="0.0 0.0 0.0"/>
    </inertial>
  </link>
  <joint name="Head/Touch/Middle_sensor_fixedjoint" type="fixed">
    <parent link="Head"/>
    <child link="HeadTouchMiddle_frame"/>
    <origin rpy="3.14159 -1.57079 -3.14159" xyz="0.001 0 0.1099"/>
    <axis xyz="0 0 0"/>
  </joint>
  <link name="RInfraRed_frame">
        <inertial>
      <mass value="1e-9"/>
      <inertia ixx="0.0" ixy="0.0" ixz="0.0" iyy="0.0" iyz="0.0" izz="0.0"/>
      <origin rpy="0 0 0" xyz="0.0 0.0 0.0"/>
    </inertial>
  </link>
  <joint name="InfraredR_sensor_fixedjoint" type="fixed">
    <parent link="Head"/>
    <child link="RInfraRed_frame"/>
    <origin rpy="0 0 0" xyz="0.0441 -0.0257 0.0466"/>
    <axis xyz="0 0 0"/>
  </joint>
  <link name="ChestButton_frame">
        <inertial>
      <mass value="1e-9"/>
      <inertia ixx="0.0" ixy="0.0" ixz="0.0" iyy="0.0" iyz="0.0" izz="0.0"/>
      <origin rpy="0 0 0" xyz="0.0 0.0 0.0"/>
    </inertial>
  </link>
  <joint name="ChestBoard/Button_sensor_fixedjoint" type="fixed">
    <parent link="torso"/>
    <child link="ChestButton_frame"/>
    <origin rpy="0 0 0" xyz="0.049871 0.001588 0.055163"/>
    <axis xyz="0 0 0"/>
  </joint>
  <link name="LFootBumperLeft_frame">
        <inertial>
      <mass value="1e-9"/>
      <inertia ixx="0.0" ixy="0.0" ixz="0.0" iyy="0.0" iyz="0.0" izz="0.0"/>
      <origin rpy="0 0 0" xyz="0.0 0.0 0.0"/>
    </inertial>
  </link>
  <joint name="LFoot/Bumper/Left_sensor_fixedjoint" type="fixed">
    <parent link="l_ankle"/>
    <child link="LFootBumperLeft_frame"/>
    <origin rpy="0 0 0" xyz="0.0876 0.019 -0.0353"/>
    <axis xyz="0 0 0"/>
  </joint>

  <!-- HEAD -->
  <transmission name="HeadYaw_Transmission">
    <type>transmission_interface/SimpleTransmission</type>
    <joint name="HeadYaw">
      <hardwareInterface>PositionJointInterface</hardwareInterface>
    </joint>
    <actuator name="HeadYaw_Motor">
      <!-- Dummy Values -->
      <hardwareInterface>PositionJointInterface</hardwareInterface>
      <mechanicalReduction>150.27</mechanicalReduction>
    </actuator>
  </transmission>
  <transmission name="HeadPitch_Transmission">
    <type>transmission_interface/SimpleTransmission</type>
    <joint name="HeadPitch">
      <hardwareInterface>PositionJointInterface</hardwareInterface>
    </joint>
    <actuator name="HeadPitch_Motor">
      <!-- Dummy Values -->
      <hardwareInterface>PositionJointInterface</hardwareInterface>
      <mechanicalReduction>173.22</mechanicalReduction>
    </actuator>
  </transmission>
  <transmission name="LShoulderPitch_Transmission">
    <type>transmission_interface/SimpleTransmission</type>
    <joint name="LShoulderPitch">
      <hardwareInterface>PositionJointInterface</hardwareInterface>
    </joint>
    <actuator name="LShoulderPitch_Motor">
      <hardwareInterface>PositionJointInterface</hardwareInterface>
      <mechanicalReduction>150.27</mechanicalReduction>
    </actuator>
  </transmission>
  <transmission name="LShoulderRoll_Transmission">
    <type>transmission_interface/SimpleTransmission</type>
    <joint name="LShoulderRoll">
      <hardwareInterface>PositionJointInterface</hardwareInterface>
    </joint>
    <actuator name="LShoulderRoll_Motor">
      <hardwareInterface>PositionJointInterface</hardwareInterface>
      <mechanicalReduction>173.22</mechanicalReduction>
    </actuator>
  </transmission>
  <transmission name="LElbowYaw_Transmission">
    <type>transmission_interface/SimpleTransmission</type>
    <joint name="LElbowYaw">
      <hardwareInterface>PositionJointInterface</hardwareInterface>
    </joint>
    <actuator name="LElbowYaw_Motor">
      <hardwareInterface>PositionJointInterface</hardwareInterface>
      <mechanicalReduction>150.27</mechanicalReduction>
    </actuator>
  </transmission>
  <transmission name="RShoulderPitch_Transmission">
    <type>transmission_interface/SimpleTransmission</type>
    <joint name="RShoulderPitch">
      <hardwareInterface>PositionJointInterface</hardwareInterface>
    </joint>
    <actuator name="RShoulderPitch_Motor">
      <hardwareInterface>PositionJointInterface</hardwareInterface>
      <mechanicalReduction>150.27</mechanicalReduction>
    </actuator>
  </transmission>
  <transmission name="RShoulderRoll_Transmission">
    <type>transmission_interface/SimpleTransmission</type>
    <joint name="RShoulderRoll">
      <hardwareInterface>PositionJointInterface</hardwareInterface>
    </joint>
    <actuator name="RShoulderRoll_Motor">
      <hardwareInterface>PositionJointInterface</hardwareInterface>
      <mechanicalReduction>173.22</mechanicalReduction>
    </actuator>
  </transmission>
  <transmission name="RElbowYaw_Transmission">
    <type>transmission_interface/SimpleTransmission</type>
    <joint name="RElbowYaw">
      <hardwareInterface>PositionJointInterface</hardwareInterface>
    </joint>
    <actuator name="RElbowYaw_Motor">
      <hardwareInterface>PositionJointInterface</hardwareInterface>
      <mechanicalReduction>150.27</mechanicalReduction>
    </actuator>
  </transmission>
  <transmission name="LHipYawPitch_Transmission">
    <type>transmission_interface/SimpleTransmission</type>
    <joint name="LHipYawPitch">
      <hardwareInterface>PositionJointInterface</hardwareInterface>
    </joint>
    <actuator name="LHipYawPitch_Motor">
      <!-- Dummy Values -->
      <hardwareInterface>PositionJointInterface</hardwareInterface>
      <mechanicalReduction>201.3</mechanicalReduction>
    </actuator>
  </transmission>
  <transmission name="LHipRoll_Transmission">
    <type>transmission_interface/SimpleTransmission</type>
    <joint name="LHipRoll">
      <hardwareInterface>PositionJointInterface</hardwareInterface>
    </joint>
    <actuator name="LHipRoll_Motor">
      <!-- Dummy Values -->
      <hardwareInterface>PositionJointInterface</hardwareInterface>
      <mechanicalReduction>201.3</mechanicalReduction>
    </actuator>
  </transmission>
  <transmission name="LHipPitch_Transmission">
    <type>transmission_interface/SimpleTransmission</type>
    <joint name="LHipPitch">
      <hardwareInterface>PositionJointInterface</hardwareInterface>
    </joint>
    <actuator name="LHipPitch_Motor">
      <!-- Dummy Values -->
      <hardwareInterface>PositionJointInterface</hardwareInterface>
      <mechanicalReduction>130.85</mechanicalReduction>
    </actuator>
  </transmission>
  <transmission name="LKneePitch_Transmission">
    <type>transmission_interface/SimpleTransmission</type>
    <joint name="LKneePitch">
      <hardwareInterface>PositionJointInterface</hardwareInterface>
    </joint>
    <actuator name="LKneePitch_Motor">
      <!-- Dummy Values -->
      <hardwareInterface>PositionJointInterface</hardwareInterface>
      <mechanicalReduction>130.85</mechanicalReduction>
    </actuator>
  </transmission>
  <transmission name="LAnklePitch_Transmission">
    <type>transmission_interface/SimpleTransmission</type>
    <joint name="LAnklePitch">
      <hardwareInterface>PositionJointInterface</hardwareInterface>
    </joint>
    <actuator name="LAnklePitch_Motor">
      <!-- Dummy Values -->
      <hardwareInterface>PositionJointInterface</hardwareInterface>
      <mechanicalReduction>130.85</mechanicalReduction>
    </actuator>
  </transmission>
  <transmission name="LAnkleRoll_Transmission">
    <type>transmission_interface/SimpleTransmission</type>
    <joint name="LAnkleRoll">
      <hardwareInterface>PositionJointInterface</hardwareInterface>
    </joint>
    <actuator name="LAnkleRoll_Motor">
      <!-- Dummy Values -->
      <hardwareInterface>PositionJointInterface</hardwareInterface>
      <mechanicalReduction>201.3</mechanicalReduction>
    </actuator>
  </transmission>
  <transmission name="RHipYawPitch_Transmission">
    <type>transmission_interface/SimpleTransmission</type>
    <joint name="RHipYawPitch">
      <hardwareInterface>PositionJointInterface</hardwareInterface>
    </joint>
    <actuator name="RHipYawPitch_Motor">
      <!-- Dummy Values -->
      <hardwareInterface>PositionJointInterface</hardwareInterface>
      <mechanicalReduction>201.3</mechanicalReduction>
    </actuator>
  </transmission>
  <transmission name="RHipRoll_Transmission">
    <type>transmission_interface/SimpleTransmission</type>
    <joint name="RHipRoll">
      <hardwareInterface>PositionJointInterface</hardwareInterface>
    </joint>
    <actuator name="RHipRoll_Motor">
      <!-- Dummy Values -->
      <hardwareInterface>PositionJointInterface</hardwareInterface>
      <mechanicalReduction>201.3</mechanicalReduction>
    </actuator>
  </transmission>
  <transmission name="RHipPitch_Transmission">
    <type>transmission_interface/SimpleTransmission</type>
    <joint name="RHipPitch">
      <hardwareInterface>PositionJointInterface</hardwareInterface>
    </joint>
    <actuator name="RHipPitch_Motor">
      <!-- Dummy Values -->
      <hardwareInterface>PositionJointInterface</hardwareInterface>
      <mechanicalReduction>130.85</mechanicalReduction>
    </actuator>
  </transmission>
  <transmission name="RKneePitch_Transmission">
    <type>transmission_interface/SimpleTransmission</type>
    <joint name="RKneePitch">
      <hardwareInterface>PositionJointInterface</hardwareInterface>
    </joint>
    <actuator name="RKneePitch_Motor">
      <!-- Dummy Values -->
      <hardwareInterface>PositionJointInterface</hardwareInterface>
      <mechanicalReduction>130.85</mechanicalReduction>
    </actuator>
  </transmission>
  <transmission name="RAnklePitch_Transmission">
    <type>transmission_interface/SimpleTransmission</type>
    <joint name="RAnklePitch">
      <hardwareInterface>PositionJointInterface</hardwareInterface>
    </joint>
    <actuator name="RAnklePitch_Motor">
      <!-- Dummy Values -->
      <hardwareInterface>PositionJointInterface</hardwareInterface>
      <mechanicalReduction>130.85</mechanicalReduction>
    </actuator>
  </transmission>
  <transmission name="RAnkleRoll_Transmission">
    <type>transmission_interface/SimpleTransmission</type>
    <joint name="RAnkleRoll">
      <hardwareInterface>PositionJointInterface</hardwareInterface>
    </joint>
    <actuator name="RAnkleRoll_Motor">
      <!-- Dummy Values -->
      <hardwareInterface>PositionJointInterface</hardwareInterface>
      <mechanicalReduction>201.3</mechanicalReduction>
    </actuator>
  </transmission>
</robot>
