<?xml version="1.0" ?>
<robot xmlns:xacro="http://ros.org/wiki/xacro">

	<xacro:property name="pi" value="3.141592654" />

	<xacro:macro name="robotis_op2_head" params="parent">

		<joint name="HeadPan" type="revolute">
			<parent link="${parent}"/>
			<child link="HeadPan_link"/>
			<origin xyz="0 0 0.0205" rpy="0 0 0" />
    			<axis xyz="0 0 1" />
    			<limit effort="2.8" velocity="5.6548668" lower="-2.6179939" upper="2.6179939" />
  		</joint>
        	<xacro:insert_transmission name="HeadPan" />

	        <!-- head pan link -->
		<link name="HeadPan_link">
			<visual>
		        	<xacro:insert_mesh_HeadPan_link />
	        	</visual>
	        	<collision>
	            		<xacro:insert_mesh_HeadPan_link />
	        	</collision>
	        	<inertial>
	            		<xacro:insert_inertia_HeadPan_link />
	        	</inertial>
	    	</link>

		<joint name="HeadTilt" type="revolute">
			<parent link="HeadPan_link"/>
			<child link="HeadTilt_link"/>
    			<origin xyz="0 0 0.03" rpy="0 ${33.0*pi/180.0} 0" />
    			<axis xyz="0 -1 0" />
    			<limit effort="2.8" velocity="5.6548668" lower="-2.6179939" upper="2.6179939" />
  		</joint>
        	<xacro:insert_transmission name="HeadTilt" />

		<!-- head tilt link -->
		<link name="HeadTilt_link">
			<visual>
		        	<xacro:insert_mesh_HeadTilt_link />
	        	</visual>
	        	<collision>
	            		<xacro:insert_mesh_HeadTilt_link />
	        	</collision>
	        	<inertial>
	            		<xacro:insert_inertia_HeadTilt_link />
	        	</inertial>
	    	</link>

		<joint name="head_cam" type="fixed">
  			<parent link="HeadTilt_link"/>
  			<child link="head_cam_link"/>
  			<origin xyz="0.0332 0 0.0344" rpy="0 0 0" />
  		</joint>

		<!-- head camera link -->
		<link name="head_cam_link" />

	</xacro:macro>

</robot>
