<?xml version="1.0" ?>
<!-- =================================================================================== -->
<!-- |    This document was autogenerated by xacro from robotis_op2.urdf.xacro         | -->
<!-- |    EDITING THIS FILE BY HAND IS NOT RECOMMENDED                                 | -->
<!-- =================================================================================== -->
<robot name="robotis_op2">
  <!-- head links -->
  <!-- left arm links -->
  <!-- right arm links -->
  <!-- left leg links -->
  <!-- right leg links -->
  <gazebo>
    <plugin filename="libgazebo_ros_control.so" name="gazebo_ros_control">
      <robotNamespace>/robotis_op2</robotNamespace>
      <robotSimType>gazebo_ros_control/DefaultRobotHWSim</robotSimType>
    </plugin>
  </gazebo>
  <gazebo>
    <plugin filename="libgazebo_ros_p3d.so" name="ground_truth">
      <frameName>map</frameName>
      <bodyName>base_link</bodyName>
      <topicName>odom</topicName>
      <updateRate>100.0</updateRate>
    </plugin>
  </gazebo>
  <gazebo reference="base_link">
    <selfCollide>false</selfCollide>
  </gazebo>
  <!-- body link -->
  <gazebo reference="torso">
    <mu1>0.5</mu1>
    <mu2>0.5</mu2>
    <selfCollide>false</selfCollide>
  </gazebo>
  <!-- head links -->
  <gazebo reference="HeadPan_link">
    <mu1>0.5</mu1>
    <mu2>0.5</mu2>
    <selfCollide>false</selfCollide>
  </gazebo>
  <gazebo reference="head">
    <mu1>0.5</mu1>
    <mu2>0.5</mu2>
    <selfCollide>false</selfCollide>
  </gazebo>
  <gazebo reference="head_cam_link">
    <selfCollide>false</selfCollide>
  </gazebo>
  <!-- left arm links -->
  <gazebo reference="l_back_link">
    <selfCollide>false</selfCollide>
  </gazebo>
  <gazebo reference="l_shoulder_link">
    <mu1>0.5</mu1>
    <mu2>0.5</mu2>
    <selfCollide>false</selfCollide>
  </gazebo>
  <gazebo reference="l_upper_arm">
    <mu1>0.5</mu1>
    <mu2>0.5</mu2>
    <selfCollide>false</selfCollide>
  </gazebo>
  <gazebo reference="l_lower_arm">
    <mu1>0.5</mu1>
    <mu2>0.5</mu2>
    <selfCollide>false</selfCollide>
  </gazebo>
  <!-- right arm links -->
  <gazebo reference="r_back_link">
    <selfCollide>false</selfCollide>
  </gazebo>
  <gazebo reference="r_shoulder_link">
    <mu1>0.5</mu1>
    <mu2>0.5</mu2>
    <selfCollide>false</selfCollide>
  </gazebo>
  <gazebo reference="r_upper_arm">
    <mu1>0.5</mu1>
    <mu2>0.5</mu2>
    <selfCollide>false</selfCollide>
  </gazebo>
  <gazebo reference="r_sho_el_link">
    <mu1>0.5</mu1>
    <mu2>0.5</mu2>
    <selfCollide>false</selfCollide>
  </gazebo>
  <!-- left leg links -->
  <gazebo reference="l_hip_1">
    <mu1>0.5</mu1>
    <mu2>0.5</mu2>
    <selfCollide>false</selfCollide>
  </gazebo>
  <gazebo reference="l_hip_2">
    <mu1>0.5</mu1>
    <mu2>0.5</mu2>
    <selfCollide>false</selfCollide>
  </gazebo>
  <gazebo reference="l_hip_3">
    <mu1>0.5</mu1>
    <mu2>0.5</mu2>
    <selfCollide>false</selfCollide>
  </gazebo>
  <gazebo reference="LKnee_link">
    <mu1>0.5</mu1>
    <mu2>0.5</mu2>
    <selfCollide>false</selfCollide>
  </gazebo>
  <gazebo reference="l_ankle">
    <mu1>0.5</mu1>
    <mu2>0.5</mu2>
    <selfCollide>false</selfCollide>
  </gazebo>
  <gazebo reference="l_foot">
    <mu1>9000</mu1>
    <mu2>9000</mu2>
    <kp>1000000.0</kp>
    <kd>10.0</kd>
    <minDepth>0.001</minDepth>
    <maxContacts>1</maxContacts>
    <selfCollide>false</selfCollide>
  </gazebo>
  <!-- right leg links -->
  <gazebo reference="r_hip_1">
    <mu1>0.5</mu1>
    <mu2>0.5</mu2>
    <selfCollide>false</selfCollide>
  </gazebo>
  <gazebo reference="r_hip_2">
    <mu1>0.5</mu1>
    <mu2>0.5</mu2>
    <selfCollide>false</selfCollide>
  </gazebo>
  <gazebo reference="r_hip_3">
    <mu1>0.5</mu1>
    <mu2>0.5</mu2>
    <selfCollide>false</selfCollide>
  </gazebo>
  <gazebo reference="RKnee_link">
    <mu1>0.5</mu1>
    <mu2>0.5</mu2>
    <selfCollide>false</selfCollide>
  </gazebo>
  <gazebo reference="r_ankle">
    <mu1>0.5</mu1>
    <mu2>0.5</mu2>
    <selfCollide>false</selfCollide>
  </gazebo>
  <gazebo reference="r_foot">
    <mu1>9000</mu1>
    <mu2>9000</mu2>
    <kp>1000000.0</kp>
    <kd>10.0</kd>
    <minDepth>0.001</minDepth>
    <maxContacts>1</maxContacts>
    <selfCollide>false</selfCollide>
  </gazebo>
  <!-- head camera -->
  <gazebo reference="head_cam_link">
    <sensor name="camera" type="camera">
      <pose>-0.050000 -0.010000 0.000000 -1.5708 0.000000 -3.141592</pose>
      <camera name="__default__">
        <horizontal_fov>1.012300</horizontal_fov>
        <image>
          <width>320</width>
          <height>200</height>
        </image>
        <clip>
          <near>0.001000</near>
          <far>100.000000</far>
        </clip>
      </camera>
      <always_on>1</always_on>
      <update_rate>30.000000</update_rate>
      <visualize>1</visualize>
      <plugin filename="libgazebo_ros_camera.so" name="camera_controller">
        <alwaysOn>true</alwaysOn>
        <updateRate>30</updateRate>
        <cameraName>robotis_op2/camera</cameraName>
        <imageTopicName>image_raw</imageTopicName>
        <cameraInfoTopicName>camera_info</cameraInfoTopicName>
        <frameName>camera_link</frameName>
        <hackBaseline>0.07</hackBaseline>
        <distortionK1>0.0</distortionK1>
        <distortionK2>0.0</distortionK2>
        <distortionK3>0.0</distortionK3>
        <distortionT1>0.0</distortionT1>
        <distortionT2>0.0</distortionT2>
      </plugin>
    </sensor>
  </gazebo>
  <!-- imu sensor -->
  <gazebo>
    <plugin filename="libhector_gazebo_ros_imu.so" name="imu_frame">
      <bodyName>torso</bodyName>
      <updateRate>50</updateRate>
      <serviceName>/robotis_op2/imu_service</serviceName>
      <topicName>/robotis_op2/imu</topicName>
      <gaussianNoise>0</gaussianNoise>
      <xyzOffset>0 0 0</xyzOffset>
      <rpyOffset>0 0 -0.703220730592</rpyOffset>
    </plugin>
  </gazebo>
  <!-- base link -->
  <link name="base_link">
    <inertial><origin xyz="0 0 0" rpy="0 0 0"/><mass value="0.0001" /><inertia ixx="0.0" ixy="0.0" ixz="0.0" iyy="0.0" iyz="0.0" izz="0.0" /></inertial>
  </link>
  <joint name="base_joint" type="fixed">
    <parent link="base_link"/>
    <child link="torso"/>
    <origin rpy="0 0 0" xyz="0 0 0.0907"/>
  </joint>
  <!-- body link -->
  <link name="torso">
    <visual>
      <origin rpy="0 0 -1.570796327" xyz="0 0 0"/>
      <geometry>
        <mesh filename="package://robotis_op2_description/meshes/geo_op_body.stl" scale="0.001 0.001 0.001"/>
      </geometry>
      <material name="Grey">
        <color rgba="0.60 0.60 0.60 1.0"/>
      </material>
    </visual>
    <collision>
      <origin rpy="0 0 -1.570796327" xyz="0 0 0"/>
      <geometry>
        <mesh filename="package://robotis_op2_description/meshes/geo_op_body.stl" scale="0.001 0.001 0.001"/>
      </geometry>
      <material name="Grey">
        <color rgba="0.60 0.60 0.60 1.0"/>
      </material>
    </collision>
    <inertial>
      <origin xyz="0 0 0"/>
      <mass value="0.975"/>
      <inertia ixx="1.0" ixy="0.0" ixz="0.0" iyy="1.0" iyz="0.0" izz="0.0"/>
    </inertial>
  </link>
  <joint name="HeadPan" type="revolute">
    <parent link="torso"/>
    <child link="HeadPan_link"/>
    <origin rpy="0 0 0" xyz="0 0 0.0205"/>
    <axis xyz="0 0 1"/>
    <limit effort="2.8" lower="-2.6179939" upper="2.6179939" velocity="5.6548668"/>
  </joint>
  <transmission name="HeadPan_tran">
    <type>transmission_interface/SimpleTransmission</type>
    <joint name="HeadPan">
      <hardwareInterface>hardware_interface/EffortJointInterface</hardwareInterface>
    </joint>
    <actuator name="HeadPan_motor">
      <hardwareInterface>hardware_interface/EffortJointInterface</hardwareInterface>
      <mechanicalReduction>1</mechanicalReduction>
    </actuator>
  </transmission>
  <!-- head pan link -->
  <link name="HeadPan_link">
    <visual>
      <origin rpy="0 0 -1.570796327" xyz="0 0 0.03"/>
      <geometry>
        <mesh filename="package://robotis_op2_description/meshes/geo_op_neck.stl" scale="0.001 0.001 0.001"/>
      </geometry>
      <material name="Grey">
        <color rgba="0.60 0.60 0.60 1.0"/>
      </material>
    </visual>
    <collision>
      <origin rpy="0 0 -1.570796327" xyz="0 0 0.03"/>
      <geometry>
        <mesh filename="package://robotis_op2_description/meshes/geo_op_neck.stl" scale="0.001 0.001 0.001"/>
      </geometry>
      <material name="Grey">
        <color rgba="0.60 0.60 0.60 1.0"/>
      </material>
    </collision>
    <inertial>
      <origin xyz="0 0 0"/>
      <mass value="0.0243"/>
      <inertia ixx="1.0" ixy="0.0" ixz="0.0" iyy="1.0" iyz="0.0" izz="0.0"/>
    </inertial>
  </link>
  <joint name="HeadTilt" type="revolute">
    <parent link="HeadPan_link"/>
    <child link="head"/>
    <origin rpy="0 0.5759586532333333 0" xyz="0 0 0.03"/>
    <axis xyz="0 -1 0"/>
    <limit effort="2.8" lower="-2.6179939" upper="2.6179939" velocity="5.6548668"/>
  </joint>
  <transmission name="HeadTilt_tran">
    <type>transmission_interface/SimpleTransmission</type>
    <joint name="HeadTilt">
      <hardwareInterface>hardware_interface/EffortJointInterface</hardwareInterface>
    </joint>
    <actuator name="HeadTilt_motor">
      <hardwareInterface>hardware_interface/EffortJointInterface</hardwareInterface>
      <mechanicalReduction>1</mechanicalReduction>
    </actuator>
  </transmission>
  <!-- head tilt link -->
  <link name="head">
    <visual>
      <origin rpy="0 3.141592654 1.570796327" xyz="0 0 0"/>
      <geometry>
        <mesh filename="package://robotis_op2_description/meshes/geo_op_head.stl" scale="0.001 0.001 0.001"/>
      </geometry>
      <material name="Grey">
        <color rgba="0.60 0.60 0.60 1.0"/>
      </material>
    </visual>
    <collision>
      <origin rpy="0 3.141592654 1.570796327" xyz="0 0 0"/>
      <geometry>
        <mesh filename="package://robotis_op2_description/meshes/geo_op_head.stl" scale="0.001 0.001 0.001"/>
      </geometry>
      <material name="Grey">
        <color rgba="0.60 0.60 0.60 1.0"/>
      </material>
    </collision>
    <inertial>
      <origin xyz="0 0 0"/>
      <mass value="0.158"/>
      <inertia ixx="1.0" ixy="0.0" ixz="0.0" iyy="1.0" iyz="0.0" izz="0.0"/>
    </inertial>
  </link>
  <joint name="head_cam" type="fixed">
    <parent link="head"/>
    <child link="head_cam_link"/>
    <origin rpy="0 0 0" xyz="0.0332 0 0.0344"/>
  </joint>
  <!-- head camera link -->
  <link name="head_cam_link">
    <inertial><origin xyz="0 0 0" rpy="0 0 0"/><mass value="0.0001" /><inertia ixx="0.0" ixy="0.0" ixz="0.0" iyy="0.0" iyz="0.0" izz="0.0" /></inertial>
  </link>
  <!-- left shoulder pitch link -->
  <joint name="LShoulderPitch" type="revolute">
    <parent link="torso"/>
    <child link="l_shoulder_link"/>
    <origin rpy="0 0 0" xyz="0 0.0575 0"/>
    <axis xyz="0 1 0"/>
    <limit effort="2.8" lower="-3.14159" upper="3.14159" velocity="5.6548668"/>
  </joint>
  <transmission name="LShoulderPitch_tran">
    <type>transmission_interface/SimpleTransmission</type>
    <joint name="LShoulderPitch">
      <hardwareInterface>hardware_interface/EffortJointInterface</hardwareInterface>
    </joint>
    <actuator name="LShoulderPitch_motor">
      <hardwareInterface>hardware_interface/EffortJointInterface</hardwareInterface>
      <mechanicalReduction>1</mechanicalReduction>
    </actuator>
  </transmission>
  <link name="l_shoulder_link">
    <visual>
      <origin rpy="0 0 -1.570796327" xyz="0 0 0"/>
      <geometry>
        <mesh filename="package://robotis_op2_description/meshes/geo_op_left_shoulder.stl" scale="0.001 0.001 0.001"/>
      </geometry>
      <material name="Grey">
        <color rgba="0.60 0.60 0.60 1.0"/>
      </material>
    </visual>
    <collision>
      <origin rpy="0 0 -1.570796327" xyz="0 0 0"/>
      <geometry>
        <mesh filename="package://robotis_op2_description/meshes/geo_op_left_shoulder.stl" scale="0.001 0.001 0.001"/>
      </geometry>
      <material name="Grey">
        <color rgba="0.60 0.60 0.60 1.0"/>
      </material>
    </collision>
    <inertial>
      <origin xyz="0 0 0"/>
      <mass value="0.0259"/>
      <inertia ixx="1.0" ixy="0.0" ixz="0.0" iyy="1.0" iyz="0.0" izz="0.0"/>
    </inertial>
  </link>
  <joint name="LShoulderRoll" type="revolute">
    <parent link="l_shoulder_link"/>
    <child link="l_upper_arm"/>
    <origin rpy="0.0 0 0" xyz="0 0.0245 -0.016"/>
    <axis xyz="-1 0 0"/>
    <limit effort="2.8" lower="-3.14159" upper="0.785" velocity="5.648668"/>
  </joint>
  <transmission name="LShoulderRoll_tran">
    <type>transmission_interface/SimpleTransmission</type>
    <joint name="LShoulderRoll">
      <hardwareInterface>hardware_interface/EffortJointInterface</hardwareInterface>
    </joint>
    <actuator name="LShoulderRoll_motor">
      <hardwareInterface>hardware_interface/EffortJointInterface</hardwareInterface>
      <mechanicalReduction>1</mechanicalReduction>
    </actuator>
  </transmission>
  <!-- left shoulder roll link -->
  <link name="l_upper_arm">
    <visual>
      <origin rpy="0 0 -1.570796327" xyz="0 0 0"/>
      <geometry>
        <mesh filename="package://robotis_op2_description/meshes/geo_op_left_upper-arm.stl" scale="0.001 0.001 0.001"/>
      </geometry>
      <material name="Grey">
        <color rgba="0.60 0.60 0.60 1.0"/>
      </material>
    </visual>
    <collision>
      <origin rpy="0 0 -1.570796327" xyz="0 0 0"/>
      <geometry>
        <mesh filename="package://robotis_op2_description/meshes/geo_op_left_upper-arm.stl" scale="0.001 0.001 0.001"/>
      </geometry>
      <material name="Grey">
        <color rgba="0.60 0.60 0.60 1.0"/>
      </material>
    </collision>
    <inertial>
      <origin xyz="0 0 0"/>
      <mass value="0.168"/>
      <inertia ixx="1.0" ixy="0.0" ixz="0.0" iyy="1.0" iyz="0.0" izz="0.0"/>
    </inertial>
  </link>
  <!-- left elbow link -->
  <joint name="LElbow" type="revolute">
    <parent link="l_upper_arm"/>
    <child link="l_lower_arm"/>
    <origin rpy="0 -1.570796327 0" xyz="0.016 0 -0.06"/>
    <axis xyz="0 -1 0"/>
    <limit effort="2.8" lower="-1.5708" upper="1.5708" velocity="5.6548668"/>
  </joint>
  <transmission name="l_el_tran">
    <type>transmission_interface/SimpleTransmission</type>
    <joint name="LElbow">
      <hardwareInterface>hardware_interface/EffortJointInterface</hardwareInterface>
    </joint>
    <actuator name="l_el_motor">
      <hardwareInterface>hardware_interface/EffortJointInterface</hardwareInterface>
      <mechanicalReduction>1</mechanicalReduction>
    </actuator>
  </transmission>
  <link name="l_lower_arm">
    <visual>
      <origin rpy="0 0 -1.570796327" xyz="0 0 0"/>
      <geometry>
        <mesh filename="package://robotis_op2_description/meshes/geo_op_left_lower-arm.stl" scale="0.001 0.001 0.001"/>
      </geometry>
      <material name="Grey">
        <color rgba="0.60 0.60 0.60 1.0"/>
      </material>
    </visual>
    <collision>
      <origin rpy="0 0 -1.570796327" xyz="0 0 0"/>
      <geometry>
        <mesh filename="package://robotis_op2_description/meshes/geo_op_left_lower-arm.stl" scale="0.001 0.001 0.001"/>
      </geometry>
      <material name="Grey">
        <color rgba="0.60 0.60 0.60 1.0"/>
      </material>
    </collision>
    <inertial>
      <origin xyz="0 0 0"/>
      <mass value="0.0592"/>
      <inertia ixx="1.0" ixy="0.0" ixz="0.0" iyy="1.0" iyz="0.0" izz="0.0"/>
    </inertial>
  </link>
<link name="l_wrist">
<inertial>
<origin xyz="0 0 0" rpy="0 0 0" />
<mass value="1e-9" />
<inertia ixx="0" ixy="0" ixz="0" iyy="0" iyz="0" izz="0" />
</inertial>
</link>
<joint name="l_wrist_frame" type="fixed">
<origin xyz="-0.015 0 -0.128" rpy="0 1.57079 0" />
<parent link="l_lower_arm" />
<child link="l_wrist" />
<axis xyz="0 0 0"/>
</joint>
  <!-- right shoulder pitch link -->
  <joint name="RShoulderPitch" type="revolute">
    <parent link="torso"/>
    <child link="r_shoulder_link"/>
    <origin rpy="0 0 0" xyz="0 -0.0575 0"/>
    <axis xyz="0 -1 0"/>
    <limit effort="2.8" lower="-3.14159" upper="3.14159" velocity="5.6548668"/>
  </joint>
  <transmission name="RShoulderPitch_tran">
    <type>transmission_interface/SimpleTransmission</type>
    <joint name="RShoulderPitch">
      <hardwareInterface>hardware_interface/EffortJointInterface</hardwareInterface>
    </joint>
    <actuator name="RShoulderPitch_motor">
      <hardwareInterface>hardware_interface/EffortJointInterface</hardwareInterface>
      <mechanicalReduction>1</mechanicalReduction>
    </actuator>
  </transmission>
  <link name="r_shoulder_link">
    <visual>
      <origin rpy="0 0 -1.570796327" xyz="0 0 0"/>
      <geometry>
        <mesh filename="package://robotis_op2_description/meshes/geo_op_right_shoulder.stl" scale="0.001 0.001 0.001"/>
      </geometry>
      <material name="Grey">
        <color rgba="0.60 0.60 0.60 1.0"/>
      </material>
    </visual>
    <collision>
      <origin rpy="0 0 -1.570796327" xyz="0 0 0"/>
      <geometry>
        <mesh filename="package://robotis_op2_description/meshes/geo_op_right_shoulder.stl" scale="0.001 0.001 0.001"/>
      </geometry>
      <material name="Grey">
        <color rgba="0.60 0.60 0.60 1.0"/>
      </material>
    </collision>
    <inertial>
      <origin xyz="0 0 0"/>
      <mass value="0.0259"/>
      <inertia ixx="1.0" ixy="0.0" ixz="0.0" iyy="1.0" iyz="0.0" izz="0.0"/>
    </inertial>
  </link>
  <!-- right shoulder roll link -->
  <joint name="RShoulderRoll" type="revolute">
    <parent link="r_shoulder_link"/>
    <child link="r_upper_arm"/>
    <origin rpy="0 0 0" xyz="0 -0.0245 -0.016"/>
    <axis xyz="-1 0 0"/>
    <limit effort="2.8" lower="-0.785" upper="3.14159" velocity="5.648668"/>
  </joint>
  <transmission name="RShoulderRoll_tran">
    <type>transmission_interface/SimpleTransmission</type>
    <joint name="RShoulderRoll">
      <hardwareInterface>hardware_interface/EffortJointInterface</hardwareInterface>
    </joint>
    <actuator name="RShoulderRoll_motor">
      <hardwareInterface>hardware_interface/EffortJointInterface</hardwareInterface>
      <mechanicalReduction>1</mechanicalReduction>
    </actuator>
  </transmission>
  <link name="r_upper_arm">
    <visual>
      <origin rpy="0 0 -1.570796327" xyz="0 0 0"/>
      <geometry>
        <mesh filename="package://robotis_op2_description/meshes/geo_op_right_upper-arm.stl" scale="0.001 0.001 0.001"/>
      </geometry>
      <material name="Grey">
        <color rgba="0.60 0.60 0.60 1.0"/>
      </material>
    </visual>
    <collision>
      <origin rpy="0 0 -1.570796327" xyz="0 0 0"/>
      <geometry>
        <mesh filename="package://robotis_op2_description/meshes/geo_op_right_upper-arm.stl" scale="0.001 0.001 0.001"/>
      </geometry>
      <material name="Grey">
        <color rgba="0.60 0.60 0.60 1.0"/>
      </material>
    </collision>
    <inertial>
      <origin xyz="0 0 0"/>
      <mass value="0.168"/>
      <inertia ixx="1.0" ixy="0.0" ixz="0.0" iyy="1.0" iyz="0.0" izz="0.0"/>
    </inertial>
  </link>
  <!-- right elbow link -->
  <joint name="RElbow" type="revolute">
    <parent link="r_upper_arm"/>
    <child link="r_lower_arm"/>
    <origin rpy="0 -1.570796327 0" xyz="0.016 0 -0.06"/>
    <axis xyz="0 1 0"/>
    <limit effort="2.8" lower="-1.5708" upper="1.5708" velocity="5.6548668"/>
  </joint>
  <transmission name="r_el_tran">
    <type>transmission_interface/SimpleTransmission</type>
    <joint name="RElbow">
      <hardwareInterface>hardware_interface/EffortJointInterface</hardwareInterface>
    </joint>
    <actuator name="r_el_motor">
      <hardwareInterface>hardware_interface/EffortJointInterface</hardwareInterface>
      <mechanicalReduction>1</mechanicalReduction>
    </actuator>
  </transmission>
  <link name="r_lower_arm">
    <visual>
      <origin rpy="0 0 -1.570796327" xyz="0 0 0"/>
      <geometry>
        <mesh filename="package://robotis_op2_description/meshes/geo_op_right_lower-arm.stl" scale="0.001 0.001 0.001"/>
      </geometry>
      <material name="Grey">
        <color rgba="0.60 0.60 0.60 1.0"/>
      </material>
    </visual>
    <collision>
      <origin rpy="0 0 -1.570796327" xyz="0 0 0"/>
      <geometry>
        <mesh filename="package://robotis_op2_description/meshes/geo_op_right_lower-arm.stl" scale="0.001 0.001 0.001"/>
      </geometry>
      <material name="Grey">
        <color rgba="0.60 0.60 0.60 1.0"/>
      </material>
    </collision>
    <inertial>
      <origin xyz="0 0 0"/>
      <mass value="0.0592"/>
      <inertia ixx="1.0" ixy="0.0" ixz="0.0" iyy="1.0" iyz="0.0" izz="0.0"/>
    </inertial>
  </link>
<link name="r_wrist">
<inertial>
<origin xyz="0 0 0" rpy="0 0 0" />
<mass value="1e-9" />
<inertia ixx="0" ixy="0" ixz="0" iyy="0" iyz="0" izz="0" />
</inertial>
</link>
<joint name="r_wrist_frame" type="fixed">
<origin xyz="-0.015 0 -0.128" rpy="0 1.57079 0" />
<parent link="r_lower_arm" />
<child link="r_wrist" />
<axis xyz="0 0 0"/>
</joint>
  <!-- left hip yaw link -->
  <joint name="LHipYaw" type="revolute">
    <parent link="torso"/>
    <child link="l_hip_1"/>
    <origin rpy="0 0 0" xyz="-0.005 0.037 -0.0907"/>
    <axis xyz="0 0 -1"/>
    <limit effort="2.8" lower="-1.5708" upper="1.5708" velocity="5.6548668"/>
  </joint>
  <transmission name="LHipYaw_tran">
    <type>transmission_interface/SimpleTransmission</type>
    <joint name="LHipYaw">
      <hardwareInterface>hardware_interface/EffortJointInterface</hardwareInterface>
    </joint>
    <actuator name="LHipYaw_motor">
      <hardwareInterface>hardware_interface/EffortJointInterface</hardwareInterface>
      <mechanicalReduction>1</mechanicalReduction>
    </actuator>
  </transmission>
  <link name="l_hip_1">
    <visual>
      <origin rpy="0 0 -1.570796327" xyz="0 0 0"/>
      <geometry>
        <mesh filename="package://robotis_op2_description/meshes/geo_op_left_hip-yaw.stl" scale="0.001 0.001 0.001"/>
      </geometry>
      <material name="Grey">
        <color rgba="0.60 0.60 0.60 1.0"/>
      </material>
    </visual>
    <collision>
      <origin rpy="0 0 -1.570796327" xyz="0 0 0"/>
      <geometry>
        <mesh filename="package://robotis_op2_description/meshes/geo_op_left_hip-yaw.stl" scale="0.001 0.001 0.001"/>
      </geometry>
      <material name="Grey">
        <color rgba="0.60 0.60 0.60 1.0"/>
      </material>
    </collision>
    <inertial>
      <origin xyz="0 0 0"/>
      <mass value="0.167"/>
      <inertia ixx="1.0" ixy="0.0" ixz="0.0" iyy="1.0" iyz="0.0" izz="0.0"/>
    </inertial>
  </link>
  <!-- left hip roll link -->
  <joint name="LHipRoll" type="revolute">
    <parent link="l_hip_1"/>
    <child link="l_hip_2"/>
    <origin rpy="0 0 0" xyz="0 0 -0.0315"/>
    <axis xyz="-1 0 0"/>
    <limit effort="2.8" lower="-1.5708" upper="1.5708" velocity="5.6548668"/>
  </joint>
  <transmission name="LHipRoll_tran">
    <type>transmission_interface/SimpleTransmission</type>
    <joint name="LHipRoll">
      <hardwareInterface>hardware_interface/EffortJointInterface</hardwareInterface>
    </joint>
    <actuator name="LHipRoll_motor">
      <hardwareInterface>hardware_interface/EffortJointInterface</hardwareInterface>
      <mechanicalReduction>1</mechanicalReduction>
    </actuator>
  </transmission>
  <link name="l_hip_2">
    <visual>
      <origin rpy="0 0 -1.570796327" xyz="0 0 0"/>
      <geometry>
        <mesh filename="package://robotis_op2_description/meshes/geo_op_left_hip-roll.stl" scale="0.001 0.001 0.001"/>
      </geometry>
      <material name="Grey">
        <color rgba="0.60 0.60 0.60 1.0"/>
      </material>
    </visual>
    <collision>
      <origin rpy="0 0 -1.570796327" xyz="0 0 0"/>
      <geometry>
        <mesh filename="package://robotis_op2_description/meshes/geo_op_left_hip-roll.stl" scale="0.001 0.001 0.001"/>
      </geometry>
      <material name="Grey">
        <color rgba="0.60 0.60 0.60 1.0"/>
      </material>
    </collision>
    <inertial>
      <origin xyz="0 0 0"/>
      <mass value="0.119"/>
      <inertia ixx="1.0" ixy="0.0" ixz="0.0" iyy="1.0" iyz="0.0" izz="0.0"/>
    </inertial>
  </link>
  <!-- left hip pitch link -->
  <joint name="LHipPitch" type="revolute">
    <parent link="l_hip_2"/>
    <child link="l_hip_3"/>
    <origin rpy="0 0 0" xyz="0 0 0"/>
    <axis xyz="0 -1 0"/>
    <limit effort="2.8" lower="-2.0944" upper="1.91986" velocity="5.6548668"/>
  </joint>
  <transmission name="LHipPitch_tran">
    <type>transmission_interface/SimpleTransmission</type>
    <joint name="LHipPitch">
      <hardwareInterface>hardware_interface/EffortJointInterface</hardwareInterface>
    </joint>
    <actuator name="LHipPitch_motor">
      <hardwareInterface>hardware_interface/EffortJointInterface</hardwareInterface>
      <mechanicalReduction>1</mechanicalReduction>
    </actuator>
  </transmission>
  <link name="l_hip_3">
    <visual>
      <origin rpy="0 0 -1.570796327" xyz="0 0 0"/>
      <geometry>
        <mesh filename="package://robotis_op2_description/meshes/geo_op_left_thigh.stl" scale="0.001 0.001 0.001"/>
      </geometry>
      <material name="Grey">
        <color rgba="0.60 0.60 0.60 1.0"/>
      </material>
    </visual>
    <collision>
      <origin rpy="0 0 -1.570796327" xyz="0 0 0"/>
      <geometry>
        <mesh filename="package://robotis_op2_description/meshes/geo_op_left_thigh.stl" scale="0.001 0.001 0.001"/>
      </geometry>
      <material name="Grey">
        <color rgba="0.60 0.60 0.60 1.0"/>
      </material>
    </collision>
    <inertial>
      <origin xyz="0 0 0"/>
      <mass value="0.119"/>
      <inertia ixx="1.0" ixy="0.0" ixz="0.0" iyy="1.0" iyz="0.0" izz="0.0"/>
    </inertial>
  </link>
  <!-- left knee link -->
  <joint name="LKnee" type="revolute">
    <parent link="l_hip_3"/>
    <child link="LKnee_link"/>
    <origin rpy="0 0 0" xyz="0 0 -0.093"/>
    <axis xyz="0 -1 0"/>
    <limit effort="2.8" lower="-2.96706" upper="0" velocity="5.6548668"/>
  </joint>
  <transmission name="LKnee_tran">
    <type>transmission_interface/SimpleTransmission</type>
    <joint name="LKnee">
      <hardwareInterface>hardware_interface/EffortJointInterface</hardwareInterface>
    </joint>
    <actuator name="LKnee_motor">
      <hardwareInterface>hardware_interface/EffortJointInterface</hardwareInterface>
      <mechanicalReduction>1</mechanicalReduction>
    </actuator>
  </transmission>
  <link name="LKnee_link">
    <visual>
      <origin rpy="0 0 -1.570796327" xyz="0 0 0"/>
      <geometry>
        <mesh filename="package://robotis_op2_description/meshes/geo_op_left_shin.stl" scale="0.001 0.001 0.001"/>
      </geometry>
      <material name="Grey">
        <color rgba="0.60 0.60 0.60 1.0"/>
      </material>
    </visual>
    <collision>
      <origin rpy="0 0 -1.570796327" xyz="0 0 0"/>
      <geometry>
        <mesh filename="package://robotis_op2_description/meshes/geo_op_left_shin.stl" scale="0.001 0.001 0.001"/>
      </geometry>
      <material name="Grey">
        <color rgba="0.60 0.60 0.60 1.0"/>
      </material>
    </collision>
    <inertial>
      <origin xyz="0 0 0"/>
      <mass value="0.0703"/>
      <inertia ixx="1.0" ixy="0.0" ixz="0.0" iyy="1.0" iyz="0.0" izz="0.0"/>
    </inertial>
  </link>
  <!-- left ankle pitch link -->
  <joint name="LAnklePitch" type="revolute">
    <parent link="LKnee_link"/>
    <child link="l_ankle"/>
    <origin rpy="0 0 0" xyz="0 0 -0.093"/>
    <axis xyz="0 1 0"/>
    <limit effort="2.8" lower="-1.22173" upper="1.5708" velocity="5.6548668"/>
  </joint>
  <transmission name="LAnklePitch_tran">
    <type>transmission_interface/SimpleTransmission</type>
    <joint name="LAnklePitch">
      <hardwareInterface>hardware_interface/EffortJointInterface</hardwareInterface>
    </joint>
    <actuator name="LAnklePitch_motor">
      <hardwareInterface>hardware_interface/EffortJointInterface</hardwareInterface>
      <mechanicalReduction>1</mechanicalReduction>
    </actuator>
  </transmission>
  <link name="l_ankle">
    <visual>
      <origin rpy="0 0 -1.570796327" xyz="0 0 0"/>
      <geometry>
        <mesh filename="package://robotis_op2_description/meshes/geo_op_left_ankle.stl" scale="0.001 0.001 0.001"/>
      </geometry>
      <material name="Grey">
        <color rgba="0.60 0.60 0.60 1.0"/>
      </material>
    </visual>
    <collision>
      <origin rpy="0 0 -1.570796327" xyz="0 0 0"/>
      <geometry>
        <mesh filename="package://robotis_op2_description/meshes/geo_op_left_ankle.stl" scale="0.001 0.001 0.001"/>
      </geometry>
      <material name="Grey">
        <color rgba="0.60 0.60 0.60 1.0"/>
      </material>
    </collision>
    <inertial>
      <origin xyz="0 0 0"/>
      <mass value="0.167"/>
      <inertia ixx="1.0" ixy="0.0" ixz="0.0" iyy="1.0" iyz="0.0" izz="0.0"/>
    </inertial>
  </link>
  <!-- left ankle roll link -->
  <joint name="LAnkleRoll" type="revolute">
    <parent link="l_ankle"/>
    <child link="l_foot"/>
    <origin rpy="0 0 0" xyz="0 0 0"/>
    <axis xyz="1 0 0"/>
    <limit effort="2.8" lower="-1.0472" upper="1.0472" velocity="5.6548668"/>
  </joint>
  <transmission name="LAnkleRoll_tran">
    <type>transmission_interface/SimpleTransmission</type>
    <joint name="LAnkleRoll">
      <hardwareInterface>hardware_interface/EffortJointInterface</hardwareInterface>
    </joint>
    <actuator name="LAnkleRoll_motor">
      <hardwareInterface>hardware_interface/EffortJointInterface</hardwareInterface>
      <mechanicalReduction>1</mechanicalReduction>
    </actuator>
  </transmission>
  <link name="l_foot">
    <visual>
      <origin rpy="0 0 -1.570796327" xyz="0 0 0"/>
      <geometry>
        <mesh filename="package://robotis_op2_description/meshes/geo_op_left_foot.stl" scale="0.001 0.001 0.001"/>
      </geometry>
      <material name="Grey">
        <color rgba="0.60 0.60 0.60 1.0"/>
      </material>
    </visual>
    <collision>
      <origin rpy="0 0 -1.570796327" xyz="0 0 0"/>
      <geometry>
        <mesh filename="package://robotis_op2_description/meshes/geo_op_left_foot.stl" scale="0.001 0.001 0.001"/>
      </geometry>
      <material name="Grey">
        <color rgba="0.60 0.60 0.60 1.0"/>
      </material>
    </collision>
    <inertial>
      <origin xyz="0 0 0"/>
      <mass value="0.0794"/>
      <inertia ixx="1.0" ixy="0.0" ixz="0.0" iyy="1.0" iyz="0.0" izz="0.0"/>
    </inertial>
  </link>
  <link name="l_sole">
  <inertial>
  <origin xyz="0 0 0" rpy="0 0 0" />
  <mass value="1e-9" />
  <inertia ixx="0" ixy="0" ixz="0" iyy="0" iyz="0" izz="0" />
  </inertial>
  </link>
  <joint name="l_sole_frame" type="fixed">
  <origin xyz="0 0 -0.033" rpy="0 0 0" />
  <parent link="l_foot" />
  <child link="l_sole" />
  <axis xyz="0 0 0"/>
  </joint>
  <!-- right hip yaw link -->
  <joint name="RHipYaw" type="revolute">
    <parent link="torso"/>
    <child link="r_hip_1"/>
    <origin rpy="0 0 0" xyz="-0.005 -0.037 -0.0907"/>
    <axis xyz="0 0 -1"/>
    <limit effort="2.8" lower="-1.5708" upper="1.5708" velocity="5.6548668"/>
  </joint>
  <transmission name="RHipYaw_tran">
    <type>transmission_interface/SimpleTransmission</type>
    <joint name="RHipYaw">
      <hardwareInterface>hardware_interface/EffortJointInterface</hardwareInterface>
    </joint>
    <actuator name="RHipYaw_motor">
      <hardwareInterface>hardware_interface/EffortJointInterface</hardwareInterface>
      <mechanicalReduction>1</mechanicalReduction>
    </actuator>
  </transmission>
  <link name="r_hip_1">
    <visual>
      <origin rpy="0 0 -1.570796327" xyz="0 0 0"/>
      <geometry>
        <mesh filename="package://robotis_op2_description/meshes/geo_op_right_hip-yaw.stl" scale="0.001 0.001 0.001"/>
      </geometry>
      <material name="Grey">
        <color rgba="0.60 0.60 0.60 1.0"/>
      </material>
    </visual>
    <collision>
      <origin rpy="0 0 -1.570796327" xyz="0 0 0"/>
      <geometry>
        <mesh filename="package://robotis_op2_description/meshes/geo_op_right_hip-yaw.stl" scale="0.001 0.001 0.001"/>
      </geometry>
      <material name="Grey">
        <color rgba="0.60 0.60 0.60 1.0"/>
      </material>
    </collision>
    <inertial>
      <origin xyz="0 0 0"/>
      <mass value="0.167"/>
      <inertia ixx="1.0" ixy="0.0" ixz="0.0" iyy="1.0" iyz="0.0" izz="0.0"/>
    </inertial>
  </link>
  <!-- right hip roll link -->
  <joint name="RHipRoll" type="revolute">
    <parent link="r_hip_1"/>
    <child link="r_hip_2"/>
    <origin rpy="0 0 0" xyz="0 0 -0.0315"/>
    <axis xyz="-1 0 0"/>
    <limit effort="2.8" lower="-1.5708" upper="1.5708" velocity="5.6548668"/>
  </joint>
  <transmission name="RHipRoll_tran">
    <type>transmission_interface/SimpleTransmission</type>
    <joint name="RHipRoll">
      <hardwareInterface>hardware_interface/EffortJointInterface</hardwareInterface>
    </joint>
    <actuator name="RHipRoll_motor">
      <hardwareInterface>hardware_interface/EffortJointInterface</hardwareInterface>
      <mechanicalReduction>1</mechanicalReduction>
    </actuator>
  </transmission>
  <link name="r_hip_2">
    <visual>
      <origin rpy="0 0 -1.570796327" xyz="0 0 0"/>
      <geometry>
        <mesh filename="package://robotis_op2_description/meshes/geo_op_right_hip-roll.stl" scale="0.001 0.001 0.001"/>
      </geometry>
      <material name="Grey">
        <color rgba="0.60 0.60 0.60 1.0"/>
      </material>
    </visual>
    <collision>
      <origin rpy="0 0 -1.570796327" xyz="0 0 0"/>
      <geometry>
        <mesh filename="package://robotis_op2_description/meshes/geo_op_right_hip-roll.stl" scale="0.001 0.001 0.001"/>
      </geometry>
      <material name="Grey">
        <color rgba="0.60 0.60 0.60 1.0"/>
      </material>
    </collision>
    <inertial>
      <origin xyz="0 0 0"/>
      <mass value="0.119"/>
      <inertia ixx="1.0" ixy="0.0" ixz="0.0" iyy="1.0" iyz="0.0" izz="0.0"/>
    </inertial>
  </link>
  <!-- right hip pitch link -->
  <joint name="RHipPitch" type="revolute">
    <parent link="r_hip_2"/>
    <child link="r_hip_3"/>
    <origin rpy="0 0 0" xyz="0 0 0"/>
    <axis xyz="0 1 0"/>
    <limit effort="2.8" lower="-2.0944" upper="1.91986" velocity="5.6548668"/>
  </joint>
  <transmission name="RHipPitch_tran">
    <type>transmission_interface/SimpleTransmission</type>
    <joint name="RHipPitch">
      <hardwareInterface>hardware_interface/EffortJointInterface</hardwareInterface>
    </joint>
    <actuator name="RHipPitch_motor">
      <hardwareInterface>hardware_interface/EffortJointInterface</hardwareInterface>
      <mechanicalReduction>1</mechanicalReduction>
    </actuator>
  </transmission>
  <link name="r_hip_3">
    <visual>
      <origin rpy="0 0 -1.570796327" xyz="0 0 0"/>
      <geometry>
        <mesh filename="package://robotis_op2_description/meshes/geo_op_right_thigh.stl" scale="0.001 0.001 0.001"/>
      </geometry>
      <material name="Grey">
        <color rgba="0.60 0.60 0.60 1.0"/>
      </material>
    </visual>
    <collision>
      <origin rpy="0 0 -1.570796327" xyz="0 0 0"/>
      <geometry>
        <mesh filename="package://robotis_op2_description/meshes/geo_op_right_thigh.stl" scale="0.001 0.001 0.001"/>
      </geometry>
      <material name="Grey">
        <color rgba="0.60 0.60 0.60 1.0"/>
      </material>
    </collision>
    <inertial>
      <origin xyz="0 0 0"/>
      <mass value="0.119"/>
      <inertia ixx="1.0" ixy="0.0" ixz="0.0" iyy="1.0" iyz="0.0" izz="0.0"/>
    </inertial>
  </link>
  <!-- right knee link -->
  <joint name="RKnee" type="revolute">
    <parent link="r_hip_3"/>
    <child link="RKnee_link"/>
    <origin rpy="0 0 0" xyz="0 0 -0.093"/>
    <axis xyz="0 1 0"/>
    <limit effort="2.8" lower="0" upper="2.96706" velocity="5.6548668"/>
  </joint>
  <transmission name="RKnee_tran">
    <type>transmission_interface/SimpleTransmission</type>
    <joint name="RKnee">
      <hardwareInterface>hardware_interface/EffortJointInterface</hardwareInterface>
    </joint>
    <actuator name="RKnee_motor">
      <hardwareInterface>hardware_interface/EffortJointInterface</hardwareInterface>
      <mechanicalReduction>1</mechanicalReduction>
    </actuator>
  </transmission>
  <link name="RKnee_link">
    <visual>
      <origin rpy="0 0 -1.570796327" xyz="0 0 -0.093"/>
      <geometry>
        <mesh filename="package://robotis_op2_description/meshes/geo_op_right_shin.stl" scale="0.001 0.001 0.001"/>
      </geometry>
      <material name="Grey">
        <color rgba="0.60 0.60 0.60 1.0"/>
      </material>
    </visual>
    <collision>
      <origin rpy="0 0 -1.570796327" xyz="0 0 -0.093"/>
      <geometry>
        <mesh filename="package://robotis_op2_description/meshes/geo_op_right_shin.stl" scale="0.001 0.001 0.001"/>
      </geometry>
      <material name="Grey">
        <color rgba="0.60 0.60 0.60 1.0"/>
      </material>
    </collision>
    <inertial>
      <origin xyz="0 0 0"/>
      <mass value="0.0703"/>
      <inertia ixx="1.0" ixy="0.0" ixz="0.0" iyy="1.0" iyz="0.0" izz="0.0"/>
    </inertial>
  </link>
  <!-- right ankle pitch link -->
  <joint name="RAnklePitch" type="revolute">
    <parent link="RKnee_link"/>
    <child link="r_ankle"/>
    <origin rpy="0 0 0" xyz="0 0 -0.093"/>
    <axis xyz="0 -1 0"/>
    <limit effort="2.8" lower="-1.5708" upper="1.22173" velocity="5.6548668"/>
  </joint>
  <transmission name="RAnklePitch_tran">
    <type>transmission_interface/SimpleTransmission</type>
    <joint name="RAnklePitch">
      <hardwareInterface>hardware_interface/EffortJointInterface</hardwareInterface>
    </joint>
    <actuator name="RAnklePitch_motor">
      <hardwareInterface>hardware_interface/EffortJointInterface</hardwareInterface>
      <mechanicalReduction>1</mechanicalReduction>
    </actuator>
  </transmission>
  <link name="r_ankle">
    <visual>
      <origin rpy="0 0 -1.570796327" xyz="0 0 0"/>
      <geometry>
        <mesh filename="package://robotis_op2_description/meshes/geo_op_right_ankle.stl" scale="0.001 0.001 0.001"/>
      </geometry>
      <material name="Grey">
        <color rgba="0.60 0.60 0.60 1.0"/>
      </material>
    </visual>
    <collision>
      <origin rpy="0 0 -1.570796327" xyz="0 0 0"/>
      <geometry>
        <mesh filename="package://robotis_op2_description/meshes/geo_op_right_ankle.stl" scale="0.001 0.001 0.001"/>
      </geometry>
      <material name="Grey">
        <color rgba="0.60 0.60 0.60 1.0"/>
      </material>
    </collision>
    <inertial>
      <origin xyz="0 0 0"/>
      <mass value="0.167"/>
      <inertia ixx="1.0" ixy="0.0" ixz="0.0" iyy="1.0" iyz="0.0" izz="0.0"/>
    </inertial>
  </link>
  <!-- right ankle roll link -->
  <joint name="RAnkleRoll" type="revolute">
    <parent link="r_ankle"/>
    <child link="r_foot"/>
    <origin rpy="0 0 0" xyz="0 0 0"/>
    <axis xyz="1 0 0"/>
    <limit effort="2.8" lower="-1.0472" upper="1.0472" velocity="5.6548668"/>
  </joint>
  <transmission name="RAnkleRoll_tran">
    <type>transmission_interface/SimpleTransmission</type>
    <joint name="RAnkleRoll">
      <hardwareInterface>hardware_interface/EffortJointInterface</hardwareInterface>
    </joint>
    <actuator name="RAnkleRoll_motor">
      <hardwareInterface>hardware_interface/EffortJointInterface</hardwareInterface>
      <mechanicalReduction>1</mechanicalReduction>
    </actuator>
  </transmission>
  <link name="r_foot">
    <visual>
      <origin rpy="0 0 -1.570796327" xyz="0 0 0"/>
      <geometry>
        <mesh filename="package://robotis_op2_description/meshes/geo_op_right_foot.stl" scale="0.001 0.001 0.001"/>
      </geometry>
      <material name="Grey">
        <color rgba="0.60 0.60 0.60 1.0"/>
      </material>
    </visual>
    <collision>
      <origin rpy="0 0 -1.570796327" xyz="0 0 0"/>
      <geometry>
        <mesh filename="package://robotis_op2_description/meshes/geo_op_right_foot.stl" scale="0.001 0.001 0.001"/>
      </geometry>
      <material name="Grey">
        <color rgba="0.60 0.60 0.60 1.0"/>
      </material>
    </collision>
    <inertial>
      <origin xyz="0 0 0"/>
      <mass value="0.0794"/>
      <inertia ixx="1.0" ixy="0.0" ixz="0.0" iyy="1.0" iyz="0.0" izz="0.0"/>
    </inertial>
  </link>
<link name="r_sole">
<inertial>
<origin xyz="0 0 0" rpy="0 0 0" />
<mass value="1e-9" />
<inertia ixx="0" ixy="0" ixz="0" iyy="0" iyz="0" izz="0" />
</inertial>
</link>
<joint name="r_sole_frame" type="fixed">
<origin xyz="0 0 -0.033" rpy="0 0 0" />
<parent link="r_foot" />
<child link="r_sole" />
<axis xyz="0 0 0"/>
</joint>
<link name="imu_frame">
<inertial>
<origin xyz="0 0 0" rpy="0 0 0" />
<mass value="1e-9" />
<inertia ixx="0" ixy="0" ixz="0" iyy="0" iyz="0" izz="0" />
</inertial>
</link>
<joint name="imu_frame_frame" type="fixed">
<origin xyz="0 0 0 " rpy="0 0 0" />
<parent link="base_link" />
<child link="imu_frame" />
<axis xyz="0 0 0"/>
</joint>
</robot>
